Workbook

Sheet SamplingMethod
A1: collection_method_id | B1: method_uri | C1: label | D1: description | E1: def | F1: note | G1: source
A2: 64 | B2: secm:ses200 | C2: Agassiz trawl | D2: =E2&IF(ISBLANK(F2),"",". "&F2) -> Nets towed over the sea floor to sample species living on or near the bottom, with single rectangular mouth piece, a conical filtering net, and equipped with closing mouth mechanism. | E2: Nets towed over the sea floor to sample species living on or near the bottom, with single rectangular mouth piece, a conical filtering net, and equipped with closing mouth mechanism. | G2: <http://vocab.nerc.ac.uk/collection/L22/current/TOOL0991/1>
A3: 21 | B3: secm:core_air | C3: Air cooled core drilling | D3: =E3&IF(ISBLANK(F3),"",". "&F3) -> Rock or sediment core derived from a dry, air-cooled diamond drilling method. | E3: Rock or sediment core derived from a dry, air-cooled diamond drilling method. | G3: Geoscience Australia
A4: 1 | B4: secm:airfall_dust_collector | C4: Airfall dust collection | D4: =E4&IF(ISBLANK(F4),"",". "&F4) -> Sample of fine-grained solid material that is passively collected by airfall from the atmosphere. | E4: Sample of fine-grained solid material that is passively collected by airfall from the atmosphere. | G4: Geoscience Australia
A5: 2 | B5: secm:airlift | C5: Airlift water sampling | D5: =E5&IF(ISBLANK(F5),"",". "&F5) -> Compressed air is used to extract groundwater | E5: Compressed air is used to extract groundwater | G5: Geoscience Australia
A6: 3 | B6: secm:artesian_flow | C6: Artesian flow sampling | D6: =E6&IF(ISBLANK(F6),"",". "&F6) -> Groundwater sample obtained from flowing artesian bore | E6: Groundwater sample obtained from flowing artesian bore | G6: Geoscience Australia
A7: 4 | B7: secm:auger | C7: Auger | D7: =E7&IF(ISBLANK(F7),"",". "&F7) -> Specimens collected by hand or mechanical auger which enable samples to be taken at intervals down profile. For example regolith, soil or sediment. | E7: Specimens collected by hand or mechanical auger which enable samples to be taken at intervals down profile. For example regolith, soil or sediment. | G7: Geoscience Australia
A8: 66 | B8: secm:ses202 | C8: Backhoe | D8: =E8&IF(ISBLANK(F8),"",". "&F8)
A9: 67 | B9: secm:ses203 | C9: Beam trawl | D9: =E9&IF(ISBLANK(F9),"",". "&F9) -> Nets towed over the sea floor having the horizontal net opening provided by a wooden or metal beam that disrupts the surface of the bed. | E9: Nets towed over the sea floor having the horizontal net opening provided by a wooden or metal beam that disrupts the surface of the bed. | G9: <http://vocab.nerc.ac.uk/collection/L05/current/62>
A10: 39 | B10: secm:epibenthic_sled | C10: Benthic sled sampling | D10: =E10&IF(ISBLANK(F10),"",". "&F10) -> A method designed to collect benthic and benthopelagic faunas from the deep sea. The sled is made from a steel frame consisting of two skids and stabilizing planes to keep it from sinking too deep into the mud.. Sampling benthic flora and fauna using a device towed along the seafloor. The devices has have a secondary net to study plankton and can be fitted with video or stills cameras to monitor sampling in real time. https://www.ga.gov.au/scientific-topics/marine/survey-techniques/sedimentary-coring-drilling | E10: A method designed to collect benthic and benthopelagic faunas from the deep sea. The sled is made from a steel frame consisting of two skids and stabilizing planes to keep it from sinking too deep into the mud. | F10: Sampling benthic flora and fauna using a device towed along the seafloor. The devices has have a secondary net to study plankton and can be fitted with video or stills cameras to monitor sampling in real time. https://www.ga.gov.au/scientific-topics/marine/survey-techniques/sedimentary-coring-drilling | G10: Geoscience Australia
A11: 6 | B11: secm:benthic_trawl | C11: Benthic trawl | D11: =E11&IF(ISBLANK(F11),"",". "&F11) -> Seabed sampling taken over a small area seaward of the continental shelf. Sample of the upper few cm of rocky sea floor particularly for biota. | E11: Seabed sampling taken over a small area seaward of the continental shelf. Sample of the upper few cm of rocky sea floor particularly for biota. | G11: Geoscience Australia
A12: 68 | B12: secm:ses204 | C12: Blake trawl | D12: =E12&IF(ISBLANK(F12),"",". "&F12)
A13: 131 | B13: secm:sm032 | C13: Blasting | D13: =E13&IF(ISBLANK(F13),"",". "&F13) -> sample collected from rock material freed from outcrop by explosives; similar to surface grab in that precise location of specimen in the rock body is not precisely known | E13: sample collected from rock material freed from outcrop by explosives; similar to surface grab in that precise location of specimen in the rock body is not precisely known | G13: SESAR collection method
A14: 5 | B14: secm:bailer | C14: Borehole bailer sampling | D14: =E14&IF(ISBLANK(F14),"",". "&F14) -> Bailer is a hollow tube used to retrieve groundwater samples from monitoring wells. A bailer is tied to a piece of rope or wire and lowered into the water column to collect a sample. | E14: Bailer is a hollow tube used to retrieve groundwater samples from monitoring wells. A bailer is tied to a piece of rope or wire and lowered into the water column to collect a sample. | G14: Geoscience Australia
A15: 7 | B15: secm:borehole_dst_test | C15: Borehole drill stem test | D15: =E15&IF(ISBLANK(F15),"",". "&F15) -> A sample is collected during drilling by a test using a hydrostatic head to measure the formation pressures and to bring the formation fluids to the surface. The test can provide information for determination of potential petroleum producing formations and their exact depth. | E15: A sample is collected during drilling by a test using a hydrostatic head to measure the formation pressures and to bring the formation fluids to the surface. The test can provide information for determination of potential petroleum producing formations and their exact depth. | G15: Geoscience Australia
A16: 8 | B16: secm:borehole_fluid_sampling | C16: Borehole fluid sampling | D16: =E16&IF(ISBLANK(F16),"",". "&F16) -> Sampling of fluids (oil, gas, or water) from a borehole by an unspecified method. | E16: Sampling of fluids (oil, gas, or water) from a borehole by an unspecified method. | G16: Geoscience Australia
A17: 9 | B17: secm:borehole_prod_test | C17: Borehole production test | D17: =E17&IF(ISBLANK(F17),"",". "&F17) -> A borehole sampling test similar to DST test, but on a larger scale and under the production conditions after the well completion is conducted. | E17: A borehole sampling test similar to DST test, but on a larger scale and under the production conditions after the well completion is conducted. | G17: Geoscience Australia
A18: 11 | B18: secm:boreholewaterpump | C18: Borehole water pumping | D18: =E18&IF(ISBLANK(F18),"",". "&F18) -> A pump designed to lift water or other fluid to the surface from a borehole. Various designs exist, including electric submersible, helical coil, jet. Include pump jacks and windmills that are specific to pumping fluid from boreholes, as well as pumps design to be placed inside the borehole | E18: A pump designed to lift water or other fluid to the surface from a borehole. Various designs exist, including electric submersible, helical coil, jet. Include pump jacks and windmills that are specific to pumping fluid from boreholes, as well as pumps design to be placed inside the borehole | G18: Geoscience Australia
A19: 10 | B19: secm:borehole_wft_test | C19: Borehole wireline formation test | D19: =E19&IF(ISBLANK(F19),"",". "&F19) -> A sample is taken from a borehole with a wireline formation tester by inserting a probe into a well wall to withdraw a small amount of formation fluid and to measure the formation pore pressure. This measurement can provide formation pressures along the well hole, thereby giving a measure of pressure with depth or along a horizontal borehole. | E19: A sample is taken from a borehole with a wireline formation tester by inserting a probe into a well wall to withdraw a small amount of formation fluid and to measure the formation pore pressure. This measurement can provide formation pressures along the well hole, thereby giving a measure of pressure with depth or along a horizontal borehole. | G19: Geoscience Australia
A20: 12 | B20: secm:bottle_incubation | C20: bottle incubation | D20: =E20&IF(ISBLANK(F20),"",". "&F20) -> A method to derive the oxygen consumption rate/respiration rates of organic matter conducted in a bottle or vial under controlled light and temperature conditions. | E20: A method to derive the oxygen consumption rate/respiration rates of organic matter conducted in a bottle or vial under controlled light and temperature conditions. | G20: Geoscience Australia
A21: 13 | B21: secm:bottle_incubation_dark | C21: bottle incubation dark | D21: =E21&IF(ISBLANK(F21),"",". "&F21) -> A method to derive the oxygen consumption rate/respiration rates of organic matter conducted in a bottle or vial under controlled light and temperature conditions. | E21: A method to derive the oxygen consumption rate/respiration rates of organic matter conducted in a bottle or vial under controlled light and temperature conditions. | G21: Geoscience Australia
A22: 14 | B22: secm:bottle_incubation_light | C22: bottle incubation light | D22: =E22&IF(ISBLANK(F22),"",". "&F22) -> A method to derive the oxygen consumption rate/respiration rates of organic matter conducted in a bottle or vial under controlled light and temperature conditions. | E22: A method to derive the oxygen consumption rate/respiration rates of organic matter conducted in a bottle or vial under controlled light and temperature conditions. | G22: Geoscience Australia
A23: 124 | B23: secm:sm025 | C23: Box coring | D23: =E23&IF(ISBLANK(F23),"",". "&F23) -> A method that obtains a large volume or large surface area core with shallow penetration and minimum disturbance. Commonly uses a double spade system. A box core uses trigger plates that contact the seafloor to close the top and bottom of a metal box plunged into the seabed. This device neatly extracts a plug of sediment that is mostly undisturbed and allows scientists to examine the layers of sediment carefully and any marine life found within. Use this category for Eckman Dredge samples as well | E23: A method that obtains a large volume or large surface area core with shallow penetration and minimum disturbance. Commonly uses a double spade system. A box core uses trigger plates that contact the seafloor to close the top and bottom of a metal box plunged into the seabed. This device neatly extracts a plug of sediment that is mostly undisturbed and allows scientists to examine the layers of sediment carefully and any marine life found within. Use this category for Eckman Dredge samples as well | G23: SESAR collection method | http://www.deepreef.org/technology/9-grab.html; http://www.eu-hermione.net/box-core; http://www.azdeq.gov/environ/water/assessment/download/sampling.pdf (Eckman dredge) | Geoscience Australia
A24: 16 | B24: secm:cable_tool_drilling | C24: cable tool drilling | D24: =E24&IF(ISBLANK(F24),"",". "&F24) -> A percussion drilling method that uses a heavy drilling tool that is raised and lowered with enough force to pulverise the rock, with the debris removed by a bailer. | E24: A percussion drilling method that uses a heavy drilling tool that is raised and lowered with enough force to pulverise the rock, with the debris removed by a bailer. | G24: National Groundwater Information System (NGIS)
A25: 69 | B25: secm:ses205 | C25: Campbell grab sampling | D25: =E25&IF(ISBLANK(F25),"",". "&F25) -> utilizes a pulley arrangement to gain extra purchase to activate a pair of jaws. Shepard (1973) reports that large Petersen grabs have been known to bring back undisturbed samples that still retain stratification characteristics. However, Schlieper (1972) points out that the tensile closing action from the attached hydrowire creates a secondary lifting force at the central axis that the two jaws pivot around, resulting in a shallower bite (5 centimeters (cm) or less), especially in firmer sediments. photo shows large jaw pincers, bigger that other grab samplers, dated 1963, so it is likely old technology no longer in use.. photo shows large jaw pincers, bigger that other grab samplers, dated 1963, so it is likely old technology no longer in use. _Campbell_ grab is a large version of a Petersen grab. https://woodshole.er.usgs.gov/openfile/of2005-1001/htmldocs/samplers/grab/campbell.htm | E25: utilizes a pulley arrangement to gain extra purchase to activate a pair of jaws. Shepard (1973) reports that large Petersen grabs have been known to bring back undisturbed samples that still retain stratification characteristics. However, Schlieper (1972) points out that the tensile closing action from the attached hydrowire creates a secondary lifting force at the central axis that the two jaws pivot around, resulting in a shallower bite (5 centimeters (cm) or less), especially in firmer sediments. photo shows large jaw pincers, bigger that other grab samplers, dated 1963, so it is likely old technology no longer in use. | F25: photo shows large jaw pincers, bigger that other grab samplers, dated 1963, so it is likely old technology no longer in use. _Campbell_ grab is a large version of a Petersen grab. https://woodshole.er.usgs.gov/openfile/of2005-1001/htmldocs/samplers/grab/campbell.htm | G25: PSEP, 1997. Recommended Guidelines for Sampling Marine Sediment, Water Column, and Tissue in Puget Sound.
A26: 70 | B26: secm:ses206 | C26: Cartridge filter filtrate | D26: =E26&IF(ISBLANK(F26),"",". "&F26) -> liquid that has been passed through a cartridge filter | E26: liquid that has been passed through a cartridge filter
A27: 71 | B27: secm:ses207 | C27: Cartridge filter residue | D27: =E27&IF(ISBLANK(F27),"",". "&F27) -> material left behind when liquid passed throught cartridge filter | E27: material left behind when liquid passed throught cartridge filter | G27: this vocabulary
A28: 104 | B28: secm:sm006 | C28: Chain bag dredge | D28: =E28&IF(ISBLANK(F28),"",". "&F28) -> Sampling of large rocks from the sea floor using a chain bag. A rock dredge is a large bag made of metal chain links attached to a simple heavy frame that keeps the bag expanded. The dredge is lowered off the back of a ship to the seafloor and dragged along to collect large pieces of rock. Because of the coarse chain links most of the finer material is washed out of the bag leaving behind the larger rock and gravel pieces within the chain bag. The dredge is then winched up to the surface and any samples are dumped onto the deck of the ship to be sorted and preserved. | E28: Sampling of large rocks from the sea floor using a chain bag. A rock dredge is a large bag made of metal chain links attached to a simple heavy frame that keeps the bag expanded. The dredge is lowered off the back of a ship to the seafloor and dragged along to collect large pieces of rock. Because of the coarse chain links most of the finer material is washed out of the bag leaving behind the larger rock and gravel pieces within the chain bag. The dredge is then winched up to the surface and any samples are dumped onto the deck of the ship to be sorted and preserved. | G28: SESAR collection method | http://www.deepreef.org/technology/79-rock-dredge.html | Geoscience Australia
A29: 72 | B29: secm:ses208 | C29: Chain saw | D29: =E29&IF(ISBLANK(F29),"",". "&F29) -> Sample extracted from feature of interest by cutting with a chain saw. | E29: Sample extracted from feature of interest by cutting with a chain saw. | G29: SESAR data
A30: 17 | B30: secm:chamber_incubation | C30: Chamber incubation | D30: =E30&IF(ISBLANK(F30),"",". "&F30) -> A method that isolates sediment and overlying water in a benthic chamber. Water samples are collected from the benthic chamber during the incubation. | E30: A method that isolates sediment and overlying water in a benthic chamber. Water samples are collected from the benthic chamber during the incubation. | G30: Geoscience Australia
A31: 18 | B31: secm:chamber_incubation_dark | C31: chamber incubation dark | D31: =E31&IF(ISBLANK(F31),"",". "&F31) -> A in situ method that isolates sediment and overlying water in a dark benthic chamber. Incubation water samples are collected from the benthic chamber during the incubation. The dark chamber restricts light penetration and therefore stops the process of photosynthesis. This enables benthic respiration to be measured. | E31: A in situ method that isolates sediment and overlying water in a dark benthic chamber. Incubation water samples are collected from the benthic chamber during the incubation. The dark chamber restricts light penetration and therefore stops the process of photosynthesis. This enables benthic respiration to be measured. | G31: Geoscience Australia
A32: 19 | B32: secm:chamber_incubation_light | C32: chamber incubation light | D32: =E32&IF(ISBLANK(F32),"",". "&F32) -> A in situ method that isolates sediment and overlying water in a light benthic chamber. Incubation water samples are collected from the benthic chamber during the incubation. The transparent walls of the chamber allow light penetration and enables benthic respiration and photosynthesis to be measured. | E32: A in situ method that isolates sediment and overlying water in a light benthic chamber. Incubation water samples are collected from the benthic chamber during the incubation. The transparent walls of the chamber allow light penetration and enables benthic respiration and photosynthesis to be measured. | G32: Geoscience Australia
A33: 114 | B33: secm:sm015 | C33: Channel sampling | D33: =E33&IF(ISBLANK(F33),"",". "&F33) -> sampling material along a channel through a feature of interest.. chip an approximately 3-inch by 3-inch (7.5 cm by 7.5 cm) channel accross the sampled feature (e.g. a coal bed) with a chisel or pick-point hammer producing fragments 2 inches (5 cm) or less across. Positioning a horizontal plastic sheet below the level of channel cutting is sometimes helpful. May also be applied to sampling at regular intervals along a channel or trench cut across a surface. | E33: sampling material along a channel through a feature of interest. | F33: chip an approximately 3-inch by 3-inch (7.5 cm by 7.5 cm) channel accross the sampled feature (e.g. a coal bed) with a chisel or pick-point hammer producing fragments 2 inches (5 cm) or less across. Positioning a horizontal plastic sheet below the level of channel cutting is sometimes helpful. May also be applied to sampling at regular intervals along a channel or trench cut across a surface. | G33: Vernon E. Swanson and Claude Huffman Jr., 1976, U. S. Geological Survey CIRCULAR 735. accessed at http://energy.er.usgs.gov/products/databases/CoalQual/Docs/c735.pdf
A34: 20 | B34: secm:chemicalseparation | C34: Chemical separation | D34: =E34&IF(ISBLANK(F34),"",". "&F34) -> sample collection by chemical processing of a sampled material | E34: sample collection by chemical processing of a sampled material | G34: this vocabulary
A35: 73 | B35: secm:ses210 | C35: Chip sampling | D35: =E35&IF(ISBLANK(F35),"",". "&F35) -> sampling over an area of a feature off interest by breaking off small pieces; produces an aggregate | E35: sampling over an area of a feature off interest by breaking off small pieces; produces an aggregate
A36: 115 | B36: secm:sm016 | C36: Collected from outcrop | D36: =E36&IF(ISBLANK(F36),"",". "&F36) -> specimen obtained by breaking piece(s) of rock from rock outcrop on surface or in a subsurface tunnel | E36: specimen obtained by breaking piece(s) of rock from rock outcrop on surface or in a subsurface tunnel | G36: this vocabulary
A37: 108 | B37: secm:sm010 | C37: Composite water sampling | D37: =E37&IF(ISBLANK(F37),"",". "&F37) -> water sample collected through some documented process over an extended water volume meant to characterize that volume e.g. a profile in a lake a stream cross section or some volume in the ocean. Many different processes may be used to collect subsamples and aggregate them into a representative single sample. | E37: water sample collected through some documented process over an extended water volume meant to characterize that volume e.g. a profile in a lake a stream cross section or some volume in the ocean. Many different processes may be used to collect subsamples and aggregate them into a representative single sample. | G37: e.g. see http://www.azdeq.gov/environ/water/assessment/download/sampling.pdf
A38: 102 | B38: secm:sm003 | C38: Composite water sampling-filter w reagent | D38: =E38&IF(ISBLANK(F38),"",". "&F38) -> composite filtered water sample preserved with reagent (e.g. nitric acid sulfuric acid) as part of sampling process | E38: composite filtered water sample preserved with reagent (e.g. nitric acid sulfuric acid) as part of sampling process | G38: e.g. see http://www.azdeq.gov/environ/water/assessment/download/sampling.pdf
A39: 100 | B39: secm:sm001 | C39: Composite water sampling- w reagent | D39: =E39&IF(ISBLANK(F39),"",". "&F39) -> composite water sample preserved with reagent (e.g. nitric acid sulfuric acid) as part of sampling process | E39: composite water sample preserved with reagent (e.g. nitric acid sulfuric acid) as part of sampling process | G39: e.g. see http://www.azdeq.gov/environ/water/assessment/download/sampling.pdf
A40: 101 | B40: secm:sm002 | C40: Composite water sampling-filter | D40: =E40&IF(ISBLANK(F40),"",". "&F40) -> composite water sample filtered as part of the sampling process (in the field or within a very short time period after collection) | E40: composite water sample filtered as part of the sampling process (in the field or within a very short time period after collection) | G40: e.g. see http://www.azdeq.gov/environ/water/assessment/download/sampling.pdf
...

Sheet Sheet1
C1: =LEN(SamplingMethod!C1) -> 5 | D1: =LEN(SamplingMethod!D1) -> 11 | E1: =LEN(SamplingMethod!E1) -> 3 | F1: =LEN(SamplingMethod!F1) -> 4 | G1: =LEN(SamplingMethod!G1) -> 6
C2: =LEN(SamplingMethod!C2) -> 13 | D2: =LEN(SamplingMethod!D2) -> 182 | G2: =LEN(SamplingMethod!G2) -> 59
C3: =LEN(SamplingMethod!C3) -> 24 | D3: =LEN(SamplingMethod!D3) -> 77 | G3: =LEN(SamplingMethod!G3) -> 20
C4: =LEN(SamplingMethod!C4) -> 23 | D4: =LEN(SamplingMethod!D4) -> 97 | G4: =LEN(SamplingMethod!G4) -> 20
C5: =LEN(SamplingMethod!C5) -> 22 | D5: =LEN(SamplingMethod!D5) -> 45 | G5: =LEN(SamplingMethod!G5) -> 20
C6: =LEN(SamplingMethod!C6) -> 22 | D6: =LEN(SamplingMethod!D6) -> 54 | G6: =LEN(SamplingMethod!G6) -> 20
C7: =LEN(SamplingMethod!C7) -> 5 | D7: =LEN(SamplingMethod!D7) -> 147 | G7: =LEN(SamplingMethod!G7) -> 20
C8: =LEN(SamplingMethod!C8) -> 7 | D8: =LEN(SamplingMethod!D8) -> 0 | G8: =LEN(SamplingMethod!G8) -> 0
C9: =LEN(SamplingMethod!C9) -> 10 | D9: =LEN(SamplingMethod!D9) -> 136 | G9: =LEN(SamplingMethod!G9) -> 51
C10: =LEN(SamplingMethod!C10) -> 21 | D10: =LEN(SamplingMethod!D10) -> 514 | G10: =LEN(SamplingMethod!G10) -> 20
C11: =LEN(SamplingMethod!C11) -> 13 | D11: =LEN(SamplingMethod!D11) -> 143 | G11: =LEN(SamplingMethod!G11) -> 20
C12: =LEN(SamplingMethod!C12) -> 11 | D12: =LEN(SamplingMethod!D12) -> 0 | G12: =LEN(SamplingMethod!G12) -> 0
C13: =LEN(SamplingMethod!C13) -> 8 | D13: =LEN(SamplingMethod!D13) -> 170 | G13: =LEN(SamplingMethod!G13) -> 23
... C156: =LEN(SamplingMethod!C156) -> 10 | D156: =LEN(SamplingMethod!D156) -> 235 | G156: =LEN(SamplingMethod!G156) -> 137

Sheet SamplingMethod-wParent
A1: [s] | B1: label | C1: def | D1: note | E1: b | F1: blabel | G1: source
A2: secm:airfall_dust_collector | B2: Airfall dust collection | C2: Sample of fine-grained solid material that is passively collected by airfall from the atmosphere. | E2: secm:sm100 | F2: Sampling method | G2: Geoscience Australia
A3: secm:airlift | B3: Airlift water sampling | C3: Compressed air is used to extract groundwater | E3: secm:sm014 | F3: Water sampling | G3: Geoscience Australia
A4: secm:airlift | B4: Airlift water sampling | C4: Compressed air is used to extract groundwater | E4: secm:borehole_fluid_sampling | F4: Borehole fluid sampling | G4: Geoscience Australia
A5: secm:artesian_flow | B5: Artesian flow sampling | C5: Groundwater sample obtained from flowing artesian bore | E5: secm:sm014 | F5: Water sampling | G5: Geoscience Australia
A6: secm:artesian_flow | B6: Artesian flow sampling | C6: Groundwater sample obtained from flowing artesian bore | E6: secm:borehole_fluid_sampling | F6: Borehole fluid sampling | G6: Geoscience Australia
A7: secm:auger | B7: Auger | C7: Specimens collected by hand or mechanical auger which enable samples to be taken at intervals down profile. For example regolith, soil or sediment. | E7: secm:drilling | F7: Drilling | G7: Geoscience Australia
A8: secm:bailer | B8: Borehole bailer sampling | C8: Bailer is a hollow tube used to retrieve groundwater samples from monitoring wells. A bailer is tied to a piece of rope or wire and lowered into the water column to collect a sample. | E8: secm:borehole_fluid_sampling | F8: Borehole fluid sampling | G8: Geoscience Australia
A9: secm:bailer | B9: Borehole bailer sampling | C9: Bailer is a hollow tube used to retrieve groundwater samples from monitoring wells. A bailer is tied to a piece of rope or wire and lowered into the water column to collect a sample. | E9: secm:sm014 | F9: Water sampling | G9: Geoscience Australia
A10: secm:benthic_trawl | B10: Benthic trawl | C10: Seabed sampling taken over a small area seaward of the continental shelf. Sample of the upper few cm of rocky sea floor particularly for biota. | E10: secm:trawlsampling | F10: Trawl sampling | G10: Geoscience Australia
A11: secm:borehole_dst_test | B11: Borehole drill stem test | C11: A sample is collected during drilling by a test using a hydrostatic head to measure the formation pressures and to bring the formation fluids to the surface. The test can provide information for determination of potential petroleum producing formations and their exact depth. | E11: secm:borehole_fluid_sampling | F11: Borehole fluid sampling | G11: Geoscience Australia
A12: secm:borehole_fluid_sampling | B12: Borehole fluid sampling | C12: Sampling of fluids (oil, gas, or water) from a borehole by an unspecified method. | E12: secm:sm043 | F12: Fluid sampling | G12: Geoscience Australia
A13: secm:borehole_prod_test | B13: Borehole production test | C13: A borehole sampling test similar to DST test, but on a larger scale and under the production conditions after the well completion is conducted. | E13: secm:borehole_fluid_sampling | F13: Borehole fluid sampling | G13: Geoscience Australia
... A20: secm:bottle_incubation_light | B20: bottle incubation light | C20: A method to derive the oxygen consumption rate/respiration rates of organic matter conducted in a bottle or vial under controlled light and temperature conditions. | E20: secm:bottle_incubation | F20: bottle incubation | G20: Geoscience Australia
A21: secm:bottlesampling | B21: Container sampling | C21: Water is collected in a container that is opened to collect water at some specific depth in a water body. Includes Niskin bottles, bottles on Rosette samplers https://en.wikipedia.org/wiki/Rosette_sampler. Also bottled samples collected by simple bailer or scoop from water surface. If water is filtered or preserved use the water sampling -filtere or -preserved categories. | D21: include Hydrothermal Fluid and Particle Sampler (HFPS) collect fluids and particles, Using a 25-port valve and two pumps, fluids are pumped through a titanium intake nozzle, through a Teflon hose and custom titanium and Teflon manifold with 24 ports. The sampler has a capacity of 18 water samples (700ml each) and 6 in-situ filters. include _Titanium major water sampler_, another tool to sample high temperature water in submarine environment. Similar to a syringe, a trigger on the outside of the bottle can be pressed by the ROV pilot to release a spring that will draw fluid into the chamber. Approximately 750ml of fluid can be collected using the Major bottles. https://oceanexplorer.noaa.gov/explorations/05lostcity/logs/july28/july28.html | E21: secm:waterbodywatersampling | F21: Water body water sampling | G21: this vocabulary
A22: secm:bottlesampling | B22: Container sampling | C22: Water is collected in a container that is opened to collect water at some specific depth in a water body. Includes Niskin bottles, bottles on Rosette samplers https://en.wikipedia.org/wiki/Rosette_sampler. Also bottled samples collected by simple bailer or scoop from water surface. If water is filtered or preserved use the water sampling -filtere or -preserved categories. | D22: include Hydrothermal Fluid and Particle Sampler (HFPS) collect fluids and particles, Using a 25-port valve and two pumps, fluids are pumped through a titanium intake nozzle, through a Teflon hose and custom titanium and Teflon manifold with 24 ports. The sampler has a capacity of 18 water samples (700ml each) and 6 in-situ filters. include _Titanium major water sampler_, another tool to sample high temperature water in submarine environment. Similar to a syringe, a trigger on the outside of the bottle can be pressed by the ROV pilot to release a spring that will draw fluid into the chamber. Approximately 750ml of fluid can be collected using the Major bottles. https://oceanexplorer.noaa.gov/explorations/05lostcity/logs/july28/july28.html | E22: secm:sm014 | F22: Water sampling | G22: this vocabulary
A23: secm:cable_tool_drilling | B23: cable tool drilling | C23: A percussion drilling method that uses a heavy drilling tool that is raised and lowered with enough force to pulverise the rock, with the debris removed by a bailer. | E23: secm:percussion_drilling | F23: Percussion drilling | G23: National Groundwater Information System (NGIS)
A24: secm:chamber_incubation | B24: Chamber incubation | C24: A method that isolates sediment and overlying water in a benthic chamber. Water samples are collected from the benthic chamber during the incubation. | E24: secm:sm200 | F24: Sediment water incubation sampling | G24: Geoscience Australia
A25: secm:chamber_incubation_dark | B25: chamber incubation dark | C25: A in situ method that isolates sediment and overlying water in a dark benthic chamber. Incubation water samples are collected from the benthic chamber during the incubation. The dark chamber restricts light penetration and therefore stops the process of photosynthesis. This enables benthic respiration to be measured. | E25: secm:chamber_incubation | F25: Chamber incubation | G25: Geoscience Australia
A26: secm:chamber_incubation_light | B26: chamber incubation light | C26: A in situ method that isolates sediment and overlying water in a light benthic chamber. Incubation water samples are collected from the benthic chamber during the incubation. The transparent walls of the chamber allow light penetration and enables benthic respiration and photosynthesis to be measured. | E26: secm:chamber_incubation | F26: Chamber incubation | G26: Geoscience Australia
A27: secm:chemicalseparation | B27: Chemical separation | C27: sample collection by chemical processing of a sampled material | E27: secm:sm045 | F27: Processed separation | G27: this vocabulary
A28: secm:core_air | B28: Air cooled core drilling | C28: Rock or sediment core derived from a dry, air-cooled diamond drilling method. | E28: secm:core_drilling_unspecified | F28: Core drilling | G28: Geoscience Australia
A29: secm:core_catcher | B29: Core catcher | C29: A method by which a specimen of sediment is collected from the end of the core in the core catcher. The core catcher has curved finger-like projections that extend down to the lowest part of the core liner. The core catcher helps keep the sediment in the core liner when the core is being removed from the surface. | E29: secm:core_drilling_unspecified | F29: Core drilling | G29: Geoscience Australia
A30: secm:core_conventional | B30: core conventional | C30: Core drilling using diamond or tungsten carbide bit using a core barrel with fibreglass inner sleeves. Used in the oil industry. | E30: secm:core_diamond | F30: Diamond bit drill coring | G30: Geoscience Australia
A31: secm:core_cutter | B31: Core cutter | C31: A method by which a specimen of sediment is collected from the lowest part of a coring assembly at the core cutter. The core cutter has sharp edges which cut and shape the sediment entering the core liner as the corer goes into the sediment. | E31: secm:core_drilling_unspecified | F31: Core drilling | G31: Geoscience Australia
A32: secm:core_diamond | B32: Diamond bit drill coring | C32: Rock or sediment core drilling using a liquid-cooled, diamond or tungsten carbide bit. | E32: secm:core_drilling_unspecified | F32: Core drilling | G32: Geoscience Australia
A33: secm:core_drilling_unspecified | B33: Core drilling | C33: Sampling of a core of earth material by an unspecified drilling method | E33: secm:sm041 | F33: Coring | G33: Geoscience Australia
A34: secm:core_drilling_unspecified | B34: Core drilling | C34: Sampling of a core of earth material by an unspecified drilling method | E34: secm:sm041 | F34: Coring | G34: SESAR collection method
... A36: secm:core_drilling_unspecified | B36: Core drilling | C36: Sampling of a core of earth material by an unspecified drilling method | E36: secm:drilling | F36: Drilling | G36: SESAR collection method
A37: secm:core_geoprobe | B37: Geoprobe coring | C37: High quality core extracted by hydraulic power. Used in rough terrain, soft sand, mud, shallow water, or tight, congested areas. Long high quality cores. | D37: [Ed. note] Geoprobe is a company that makes a variety of drilling and coring equipment; just saying 'Geoprobe' isn't obviously communicating what drilling technology is intended. | E37: secm:sm005 | F37: Soft material coring | G37: https://geoprobe.com/tooling/rock-coring-wet-rotary-systems
A38: secm:core_geoprobe | B38: Geoprobe coring | C38: High quality core extracted by hydraulic power. Used in rough terrain, soft sand, mud, shallow water, or tight, congested areas. Long high quality cores. | D38: [Ed. note] Geoprobe is a company that makes a variety of drilling and coring equipment; just saying 'Geoprobe' isn't obviously communicating what drilling technology is intended. | E38: secm:sm005 | F38: Soft material coring | G38: Geoscience Australia
A39: secm:core_incubation_dark | B39: core incubation dark | C39: A method whereby a sediment core is collected along with overlying water. The sediment and water are incubated under no light and controlled temperature conditions. | E39: secm:sm200 | F39: Sediment water incubation sampling | G39: Geoscience Australia
A40: secm:core_incubation_light | B40: core incubation light | C40: A method whereby a sediment core is collected along with overlying water. The sediment and water are incubated under controlled light and temperature conditions. | E40: secm:sm200 | F40: Sediment water incubation sampling | G40: Geoscience Australia
A41: secm:core_mackereth | B41: core Mackereth | C41: The Mackereth is a complex coring system utilizing compressed gas to penetrate and recover single-drive moderate (up to 12 m) cores from lakes of diverse depths. Mackereth cores can be deployed on virutally any small craft and and can be used in water depths up to 80 m. | E41: secm:sm005 | F41: Soft material coring | G41: Geoscience Australia
A42: secm:core_press | B42: core press | C42: Pore water is extracted from core material under pressure. | E42: secm:sm014 | F42: Water sampling | G42: Geoscience Australia
A43: secm:core_push | B43: Push coring | C43: A pipe that is pushed into the sediment to gain a core that is no longer than 2m long. Core pipe has a valve on top that is used to create a vacuum at the top of the core when pulling the core out of the sediment. Can be operated by a human working on land, shallow water, or from a boat in shallow water with a pipe extension to reach the bottom. Can be operated mechanically from a submersible (HOV or ROV). | D43: a smaller hand-held device made up of a length of clear plastic tubing attached to a corer head and extension poles. In the marine environment, the push corer is lowered overboard and manually pushed into the sediment before a valve at the top of the core, is closed creating a vacuum. The core and barrel is then lifted out of the surrounding sediment and back to the surface. The operation is the same on land or in shallow waters where a boat is not required. https://www.ga.gov.au/scientific-topics/marine/survey-techniques/sedimentary-coring-drilling | E43: secm:sm005 | F43: Soft material coring | G43: Geoscience Australia
A44: secm:core_rov | B44: Coring from submersible | C44: A core produced by a drill mounted on a submersible vehicle, ROV, HOV. | E44: secm:core_drilling_unspecified | F44: Core drilling | G44: Geoscience Australia
A45: secm:core_sonic | B45: Sonic coring | C45: Similar to the vibro-core technique, the drill stem and barrel are vibrated vertically at frequencies between 50Hz and 180Hz such that the sampler barrel advances by slicing through the regolith. | E45: secm:sm031 | F45: Vibrator Coring | G45: https://www.frtr.gov/site/3_1_6.html
A46: secm:core_sonic | B46: Sonic coring | C46: Similar to the vibro-core technique, the drill stem and barrel are vibrated vertically at frequencies between 50Hz and 180Hz such that the sampler barrel advances by slicing through the regolith. | E46: secm:sm031 | F46: Vibrator Coring | G46: Geoscience Australia
A47: secm:core_spike | B47: core spike | C47: A core of surficial material taken by driving a spike into the ground. | E47: secm:sm005 | F47: Soft material coring | G47: Geoscience Australia
...
