Workbook
Name ID: vocab!$B$2:$B$94
Name parent_term: vocab!$C$2:$C$94
Name parentID: vocab!$D$2:$D$94
Name redux: vocab!$A$2:$A$94
Name scope_note: vocab!$F$2:$F$94
Name source: vocab!$E$2:$E$94

Sheet samplemethodlookup
A1: collection_method | B1: new_label | C1: alt label | D1: method_id | E1: method_uri | F1: test
A2: Coring>JumboPistonCorer | B2: Piston coring | D2: =IFERROR(INDEX([1]SamplingMethod!$A$2:$C$160,MATCH(B2,[1]SamplingMethod!$C$2:$C$160,FALSE),1),"") -> 128 | E2: =IFERROR(INDEX([1]SamplingMethod!$A$2:$C$160,MATCH(B2,[1]SamplingMethod!$C$2:$C$160,FALSE),2),"") -> secm:sm029 | F2: =IFERROR(INDEX('collectionMethodDistinct'!$A$2:$A$646,MATCH(A2,'collectionMethodDistinct'!$A$2:$A$646,FALSE),1),"") -> Coring>JumboPistonCorer
A3: Shop bought - Northern Geological Supplies Ltd | B3: unknown | D3: =IFERROR(INDEX([1]SamplingMethod!$A$2:$C$160,MATCH(B3,[1]SamplingMethod!$C$2:$C$160,FALSE),1),"") -> 151 | E3: =IFERROR(INDEX([1]SamplingMethod!$A$2:$C$160,MATCH(B3,[1]SamplingMethod!$C$2:$C$160,FALSE),2),"") -> secm:unknown | F3: =IFERROR(INDEX('collectionMethodDistinct'!$A$2:$A$646,MATCH(A3,'collectionMethodDistinct'!$A$2:$A$646,FALSE),1),"") -> Shop bought - Northern Geological Supplies Ltd | G3: =IFERROR(INDEX($A$2:$D$585,MATCH(collectionMethodDistinct[[#This Row],[Column1]],$A$2:$A$585,FALSE),1),"") -> Coring>JumboPistonCorer
A4: Coring>HandHeldCorer | B4: Hand auger coring | D4: =IFERROR(INDEX([1]SamplingMethod!$A$2:$C$160,MATCH(B4,[1]SamplingMethod!$C$2:$C$160,FALSE),1),"") -> 105 | E4: =IFERROR(INDEX([1]SamplingMethod!$A$2:$C$160,MATCH(B4,[1]SamplingMethod!$C$2:$C$160,FALSE),2),"") -> secm:sm007 | F4: =IFERROR(INDEX('collectionMethodDistinct'!$A$2:$A$646,MATCH(A4,'collectionMethodDistinct'!$A$2:$A$646,FALSE),1),"") -> Coring>HandHeldCorer
A5: Cut from American Museum of Natural History Mineral Collection # 100242 | B5: Splitting from bulk sample | D5: =IFERROR(INDEX([1]SamplingMethod!$A$2:$C$160,MATCH(B5,[1]SamplingMethod!$C$2:$C$160,FALSE),1),"") -> 144 | E5: =IFERROR(INDEX([1]SamplingMethod!$A$2:$C$160,MATCH(B5,[1]SamplingMethod!$C$2:$C$160,FALSE),2),"") -> secm:sm046 | F5: =IFERROR(INDEX('collectionMethodDistinct'!$A$2:$A$646,MATCH(A5,'collectionMethodDistinct'!$A$2:$A$646,FALSE),1),"") -> Cut from American Museum of Natural History Mineral Collection # 100242
A6: >2 mm size fraction | B6: Sieved aggregate | D6: =IFERROR(INDEX([1]SamplingMethod!$A$2:$C$160,MATCH(B6,[1]SamplingMethod!$C$2:$C$160,FALSE),1),"") -> 92 | E6: =IFERROR(INDEX([1]SamplingMethod!$A$2:$C$160,MATCH(B6,[1]SamplingMethod!$C$2:$C$160,FALSE),2),"") -> secm:ses231 | F6: =IFERROR(INDEX('collectionMethodDistinct'!$A$2:$A$646,MATCH(A6,'collectionMethodDistinct'!$A$2:$A$646,FALSE),1),"") -> >2 mm size fraction | G6: =IFERROR(INDEX($A$2:$D$585,MATCH(collectionMethodDistinct[[#This Row],[Column1]],$A$2:$A$585,FALSE),1),"") -> Cut from American Museum of Natural History Mineral Collection # 100242
A7: >38 um size fraction | B7: Sieved aggregate | D7: =IFERROR(INDEX([1]SamplingMethod!$A$2:$C$160,MATCH(B7,[1]SamplingMethod!$C$2:$C$160,FALSE),1),"") -> 92 | E7: =IFERROR(INDEX([1]SamplingMethod!$A$2:$C$160,MATCH(B7,[1]SamplingMethod!$C$2:$C$160,FALSE),2),"") -> secm:ses231 | F7: =IFERROR(INDEX('collectionMethodDistinct'!$A$2:$A$646,MATCH(A7,'collectionMethodDistinct'!$A$2:$A$646,FALSE),1),"") -> >38 um size fraction | G7: =IFERROR(INDEX($A$2:$D$585,MATCH(collectionMethodDistinct[[#This Row],[Column1]],$A$2:$A$585,FALSE),1),"") -> >2 mm size fraction
A8: >63 um size fraction | B8: Sieved aggregate | D8: =IFERROR(INDEX([1]SamplingMethod!$A$2:$C$160,MATCH(B8,[1]SamplingMethod!$C$2:$C$160,FALSE),1),"") -> 92 | E8: =IFERROR(INDEX([1]SamplingMethod!$A$2:$C$160,MATCH(B8,[1]SamplingMethod!$C$2:$C$160,FALSE),2),"") -> secm:ses231 | F8: =IFERROR(INDEX('collectionMethodDistinct'!$A$2:$A$646,MATCH(A8,'collectionMethodDistinct'!$A$2:$A$646,FALSE),1),"") -> >63 um size fraction | G8: =IFERROR(INDEX($A$2:$D$585,MATCH(collectionMethodDistinct[[#This Row],[Column1]],$A$2:$A$585,FALSE),1),"") -> >38 um size fraction
A9: 0.22 µm, PES | B9: Water sampling-filter | D9: =IFERROR(INDEX([1]SamplingMethod!$A$2:$C$160,MATCH(B9,[1]SamplingMethod!$C$2:$C$160,FALSE),1),"") -> 122 | E9: =IFERROR(INDEX([1]SamplingMethod!$A$2:$C$160,MATCH(B9,[1]SamplingMethod!$C$2:$C$160,FALSE),2),"") -> secm:sm023 | F9: =IFERROR(INDEX('collectionMethodDistinct'!$A$2:$A$646,MATCH(A9,'collectionMethodDistinct'!$A$2:$A$646,FALSE),1),"") -> 0.22 µm, PES | G9: =IFERROR(INDEX($A$2:$D$585,MATCH(collectionMethodDistinct[[#This Row],[Column1]],$A$2:$A$585,FALSE),1),"") -> >63 um size fraction
A10: 0.22μm | B10: Water sampling-filter | D10: =IFERROR(INDEX([1]SamplingMethod!$A$2:$C$160,MATCH(B10,[1]SamplingMethod!$C$2:$C$160,FALSE),1),"") -> 122 | E10: =IFERROR(INDEX([1]SamplingMethod!$A$2:$C$160,MATCH(B10,[1]SamplingMethod!$C$2:$C$160,FALSE),2),"") -> secm:sm023 | F10: =IFERROR(INDEX('collectionMethodDistinct'!$A$2:$A$646,MATCH(A10,'collectionMethodDistinct'!$A$2:$A$646,FALSE),1),"") -> 0.22μm
A11: 0.45 µm, PES | B11: Water sampling-filter | D11: =IFERROR(INDEX([1]SamplingMethod!$A$2:$C$160,MATCH(B11,[1]SamplingMethod!$C$2:$C$160,FALSE),1),"") -> 122 | E11: =IFERROR(INDEX([1]SamplingMethod!$A$2:$C$160,MATCH(B11,[1]SamplingMethod!$C$2:$C$160,FALSE),2),"") -> secm:sm023 | F11: =IFERROR(INDEX('collectionMethodDistinct'!$A$2:$A$646,MATCH(A11,'collectionMethodDistinct'!$A$2:$A$646,FALSE),1),"") -> 0.45 µm, PES
A12: 0.45μm | B12: Water sampling-filter | D12: =IFERROR(INDEX([1]SamplingMethod!$A$2:$C$160,MATCH(B12,[1]SamplingMethod!$C$2:$C$160,FALSE),1),"") -> 122 | E12: =IFERROR(INDEX([1]SamplingMethod!$A$2:$C$160,MATCH(B12,[1]SamplingMethod!$C$2:$C$160,FALSE),2),"") -> secm:sm023 | F12: =IFERROR(INDEX('collectionMethodDistinct'!$A$2:$A$646,MATCH(A12,'collectionMethodDistinct'!$A$2:$A$646,FALSE),1),"") -> 0.45μm
A13: 0.8/0.2 micron cartridge filter (AcroPak) | B13: Water sampling-filter | D13: =IFERROR(INDEX([1]SamplingMethod!$A$2:$C$160,MATCH(B13,[1]SamplingMethod!$C$2:$C$160,FALSE),1),"") -> 122 | E13: =IFERROR(INDEX([1]SamplingMethod!$A$2:$C$160,MATCH(B13,[1]SamplingMethod!$C$2:$C$160,FALSE),2),"") -> secm:sm023 | F13: =IFERROR(INDEX('collectionMethodDistinct'!$A$2:$A$646,MATCH(A13,'collectionMethodDistinct'!$A$2:$A$646,FALSE),1),"") -> 0.8/0.2 micron cartridge filter (AcroPak)
A14: 0.8/0.2 micron cartridge filter (AcroPak), no preservative | B14: Water sampling-filter | D14: =IFERROR(INDEX([1]SamplingMethod!$A$2:$C$160,MATCH(B14,[1]SamplingMethod!$C$2:$C$160,FALSE),1),"") -> 122 | E14: =IFERROR(INDEX([1]SamplingMethod!$A$2:$C$160,MATCH(B14,[1]SamplingMethod!$C$2:$C$160,FALSE),2),"") -> secm:sm023 | F14: =IFERROR(INDEX('collectionMethodDistinct'!$A$2:$A$646,MATCH(A14,'collectionMethodDistinct'!$A$2:$A$646,FALSE),1),"") -> 0.8/0.2 micron cartridge filter (AcroPak), no preservative
A15: 2-inch diameter hand corer | B15: Hand auger coring | D15: =IFERROR(INDEX([1]SamplingMethod!$A$2:$C$160,MATCH(B15,[1]SamplingMethod!$C$2:$C$160,FALSE),1),"") -> 105 | E15: =IFERROR(INDEX([1]SamplingMethod!$A$2:$C$160,MATCH(B15,[1]SamplingMethod!$C$2:$C$160,FALSE),2),"") -> secm:sm007 | F15: =IFERROR(INDEX('collectionMethodDistinct'!$A$2:$A$646,MATCH(A15,'collectionMethodDistinct'!$A$2:$A$646,FALSE),1),"") -> 2-inch diameter hand corer
A16: 2mm sieved soil sample, quartered, ground and homogenized in an agate mill. | B16: Sieved aggregate | C16: Pulverize | D16: =IFERROR(INDEX([1]SamplingMethod!$A$2:$C$160,MATCH(B16,[1]SamplingMethod!$C$2:$C$160,FALSE),1),"") -> 92 | E16: =IFERROR(INDEX([1]SamplingMethod!$A$2:$C$160,MATCH(B16,[1]SamplingMethod!$C$2:$C$160,FALSE),2),"") -> secm:ses231 | F16: =IFERROR(INDEX('collectionMethodDistinct'!$A$2:$A$646,MATCH(A16,'collectionMethodDistinct'!$A$2:$A$646,FALSE),1),"") -> 2mm sieved soil sample, quartered, ground and homogenized in an agate mill.
A17: 4 inch hand auger | B17: Hand auger | D17: =IFERROR(INDEX([1]SamplingMethod!$A$2:$C$160,MATCH(B17,[1]SamplingMethod!$C$2:$C$160,FALSE),1),"") -> 79 | E17: =IFERROR(INDEX([1]SamplingMethod!$A$2:$C$160,MATCH(B17,[1]SamplingMethod!$C$2:$C$160,FALSE),2),"") -> secm:ses217 | F17: =IFERROR(INDEX('collectionMethodDistinct'!$A$2:$A$646,MATCH(A17,'collectionMethodDistinct'!$A$2:$A$646,FALSE),1),"") -> 4 inch hand auger
A18: Agassiz trawl | B18: Agassiz trawl | D18: =IFERROR(INDEX([1]SamplingMethod!$A$2:$C$160,MATCH(B18,[1]SamplingMethod!$C$2:$C$160,FALSE),1),"") -> 64 | E18: =IFERROR(INDEX([1]SamplingMethod!$A$2:$C$160,MATCH(B18,[1]SamplingMethod!$C$2:$C$160,FALSE),2),"") -> secm:ses200 | F18: =IFERROR(INDEX('collectionMethodDistinct'!$A$2:$A$646,MATCH(A18,'collectionMethodDistinct'!$A$2:$A$646,FALSE),1),"") -> Agassiz trawl
A19: air-dried soil sample sieved in 2mm and 250 µm mesh by mechanical agitation. | B19: Sieved aggregate | D19: =IFERROR(INDEX([1]SamplingMethod!$A$2:$C$160,MATCH(B19,[1]SamplingMethod!$C$2:$C$160,FALSE),1),"") -> 92 | E19: =IFERROR(INDEX([1]SamplingMethod!$A$2:$C$160,MATCH(B19,[1]SamplingMethod!$C$2:$C$160,FALSE),2),"") -> secm:ses231 | F19: =IFERROR(INDEX('collectionMethodDistinct'!$A$2:$A$646,MATCH(A19,'collectionMethodDistinct'!$A$2:$A$646,FALSE),1),"") -> air-dried soil sample sieved in 2mm and 250 µm mesh by mechanical agitation.
A20: Alvin | B20: Submersible grab | D20: =IFERROR(INDEX([1]SamplingMethod!$A$2:$C$160,MATCH(B20,[1]SamplingMethod!$C$2:$C$160,FALSE),1),"") -> 65 | E20: =IFERROR(INDEX([1]SamplingMethod!$A$2:$C$160,MATCH(B20,[1]SamplingMethod!$C$2:$C$160,FALSE),2),"") -> secm:ses201 | F20: =IFERROR(INDEX('collectionMethodDistinct'!$A$2:$A$646,MATCH(A20,'collectionMethodDistinct'!$A$2:$A$646,FALSE),1),"") -> Alvin
A21: ALVIN grab | B21: Submersible grab | D21: =IFERROR(INDEX([1]SamplingMethod!$A$2:$C$160,MATCH(B21,[1]SamplingMethod!$C$2:$C$160,FALSE),1),"") -> 65 | E21: =IFERROR(INDEX([1]SamplingMethod!$A$2:$C$160,MATCH(B21,[1]SamplingMethod!$C$2:$C$160,FALSE),2),"") -> secm:ses201 | F21: =IFERROR(INDEX('collectionMethodDistinct'!$A$2:$A$646,MATCH(A21,'collectionMethodDistinct'!$A$2:$A$646,FALSE),1),"") -> Alvin Grab
A22: Aquatic Instruments Universal Corer | B22: Soft material coring | D22: =IFERROR(INDEX([1]SamplingMethod!$A$2:$C$160,MATCH(B22,[1]SamplingMethod!$C$2:$C$160,FALSE),1),"") -> 103 | E22: =IFERROR(INDEX([1]SamplingMethod!$A$2:$C$160,MATCH(B22,[1]SamplingMethod!$C$2:$C$160,FALSE),2),"") -> secm:sm005 | F22: =IFERROR(INDEX('collectionMethodDistinct'!$A$2:$A$646,MATCH(A22,'collectionMethodDistinct'!$A$2:$A$646,FALSE),1),"") -> Aquatic Instruments Universal Corer
A23: Auger | B23: Auger | D23: =IFERROR(INDEX([1]SamplingMethod!$A$2:$C$160,MATCH(B23,[1]SamplingMethod!$C$2:$C$160,FALSE),1),"") -> 4 | E23: =IFERROR(INDEX([1]SamplingMethod!$A$2:$C$160,MATCH(B23,[1]SamplingMethod!$C$2:$C$160,FALSE),2),"") -> secm:auger | F23: =IFERROR(INDEX('collectionMethodDistinct'!$A$2:$A$646,MATCH(A23,'collectionMethodDistinct'!$A$2:$A$646,FALSE),1),"") -> Auger
A24: augered soil core | B24: Hand auger coring | D24: =IFERROR(INDEX([1]SamplingMethod!$A$2:$C$160,MATCH(B24,[1]SamplingMethod!$C$2:$C$160,FALSE),1),"") -> 105 | E24: =IFERROR(INDEX([1]SamplingMethod!$A$2:$C$160,MATCH(B24,[1]SamplingMethod!$C$2:$C$160,FALSE),2),"") -> secm:sm007 | F24: =IFERROR(INDEX('collectionMethodDistinct'!$A$2:$A$646,MATCH(A24,'collectionMethodDistinct'!$A$2:$A$646,FALSE),1),"") -> augered soil core
A25: Backhoe or by hand | B25: Human grab from surface | D25: =IFERROR(INDEX([1]SamplingMethod!$A$2:$C$160,MATCH(B25,[1]SamplingMethod!$C$2:$C$160,FALSE),1),"") -> 80 | E25: =IFERROR(INDEX([1]SamplingMethod!$A$2:$C$160,MATCH(B25,[1]SamplingMethod!$C$2:$C$160,FALSE),2),"") -> secm:ses218 | F25: =IFERROR(INDEX('collectionMethodDistinct'!$A$2:$A$646,MATCH(A25,'collectionMethodDistinct'!$A$2:$A$646,FALSE),1),"")
A26: Beam Trawl | B26: Beam trawl | D26: =IFERROR(INDEX([1]SamplingMethod!$A$2:$C$160,MATCH(B26,[1]SamplingMethod!$C$2:$C$160,FALSE),1),"") -> 67 | E26: =IFERROR(INDEX([1]SamplingMethod!$A$2:$C$160,MATCH(B26,[1]SamplingMethod!$C$2:$C$160,FALSE),2),"") -> secm:ses203 | F26: =IFERROR(INDEX('collectionMethodDistinct'!$A$2:$A$646,MATCH(A26,'collectionMethodDistinct'!$A$2:$A$646,FALSE),1),"") -> Beam Trawl
A27: Big Bertha | B27: Trawl sampling | D27: =IFERROR(INDEX([1]SamplingMethod!$A$2:$C$160,MATCH(B27,[1]SamplingMethod!$C$2:$C$160,FALSE),1),"") -> 149 | E27: =IFERROR(INDEX([1]SamplingMethod!$A$2:$C$160,MATCH(B27,[1]SamplingMethod!$C$2:$C$160,FALSE),2),"") -> secm:trawlsampling | F27: =IFERROR(INDEX('collectionMethodDistinct'!$A$2:$A$646,MATCH(A27,'collectionMethodDistinct'!$A$2:$A$646,FALSE),1),"") -> Big Bertha
A28: Blake Trawl | B28: Blake trawl | D28: =IFERROR(INDEX([1]SamplingMethod!$A$2:$C$160,MATCH(B28,[1]SamplingMethod!$C$2:$C$160,FALSE),1),"") -> 68 | E28: =IFERROR(INDEX([1]SamplingMethod!$A$2:$C$160,MATCH(B28,[1]SamplingMethod!$C$2:$C$160,FALSE),2),"") -> secm:ses204 | F28: =IFERROR(INDEX('collectionMethodDistinct'!$A$2:$A$646,MATCH(A28,'collectionMethodDistinct'!$A$2:$A$646,FALSE),1),"") -> Blake Trawl
A29: Blake Trawl/Menzie Trawl | B29: Blake trawl | C29: Menzie Trawl | D29: =IFERROR(INDEX([1]SamplingMethod!$A$2:$C$160,MATCH(B29,[1]SamplingMethod!$C$2:$C$160,FALSE),1),"") -> 68 | E29: =IFERROR(INDEX([1]SamplingMethod!$A$2:$C$160,MATCH(B29,[1]SamplingMethod!$C$2:$C$160,FALSE),2),"") -> secm:ses204 | F29: =IFERROR(INDEX('collectionMethodDistinct'!$A$2:$A$646,MATCH(A29,'collectionMethodDistinct'!$A$2:$A$646,FALSE),1),"") -> Blake Trawl/Menzie Trawl
A30: Blake Trawl/Menzies Trawl | B30: Blake trawl | C30: Menzie Trawl | D30: =IFERROR(INDEX([1]SamplingMethod!$A$2:$C$160,MATCH(B30,[1]SamplingMethod!$C$2:$C$160,FALSE),1),"") -> 68 | E30: =IFERROR(INDEX([1]SamplingMethod!$A$2:$C$160,MATCH(B30,[1]SamplingMethod!$C$2:$C$160,FALSE),2),"") -> secm:ses204 | F30: =IFERROR(INDEX('collectionMethodDistinct'!$A$2:$A$646,MATCH(A30,'collectionMethodDistinct'!$A$2:$A$646,FALSE),1),"") -> Blake Trawl/Menzies Trawl
A31: Blasting | B31: Blasting | D31: =IFERROR(INDEX([1]SamplingMethod!$A$2:$C$160,MATCH(B31,[1]SamplingMethod!$C$2:$C$160,FALSE),1),"") -> 131 | E31: =IFERROR(INDEX([1]SamplingMethod!$A$2:$C$160,MATCH(B31,[1]SamplingMethod!$C$2:$C$160,FALSE),2),"") -> secm:sm032 | F31: =IFERROR(INDEX('collectionMethodDistinct'!$A$2:$A$646,MATCH(A31,'collectionMethodDistinct'!$A$2:$A$646,FALSE),1),"") -> Blasting
A32: Borehole | B32: Drilling | D32: =IFERROR(INDEX([1]SamplingMethod!$A$2:$C$160,MATCH(B32,[1]SamplingMethod!$C$2:$C$160,FALSE),1),"") -> 38 | E32: =IFERROR(INDEX([1]SamplingMethod!$A$2:$C$160,MATCH(B32,[1]SamplingMethod!$C$2:$C$160,FALSE),2),"") -> secm:drilling | F32: =IFERROR(INDEX('collectionMethodDistinct'!$A$2:$A$646,MATCH(A32,'collectionMethodDistinct'!$A$2:$A$646,FALSE),1),"") -> Borehole
A33: borosilicate glass bottle, 0.8/0.2 micron cartridge filter (AcroPak), HgCl2 preservative | B33: Water sampling-filter and preserve with reagent | D33: =IFERROR(INDEX([1]SamplingMethod!$A$2:$C$160,MATCH(B33,[1]SamplingMethod!$C$2:$C$160,FALSE),1),"") -> 123 | E33: =IFERROR(INDEX([1]SamplingMethod!$A$2:$C$160,MATCH(B33,[1]SamplingMethod!$C$2:$C$160,FALSE),2),"") -> secm:sm024 | F33: =IFERROR(INDEX('collectionMethodDistinct'!$A$2:$A$646,MATCH(A33,'collectionMethodDistinct'!$A$2:$A$646,FALSE),1),"") -> borosilicate glass bottle, 0.8/0.2 micron cartridge filter (AcroPak), HgCl2 preservative
A34: Box corer | B34: Box coring | D34: =IFERROR(INDEX([1]SamplingMethod!$A$2:$C$160,MATCH(B34,[1]SamplingMethod!$C$2:$C$160,FALSE),1),"") -> 124 | E34: =IFERROR(INDEX([1]SamplingMethod!$A$2:$C$160,MATCH(B34,[1]SamplingMethod!$C$2:$C$160,FALSE),2),"") -> secm:sm025 | F34: =IFERROR(INDEX('collectionMethodDistinct'!$A$2:$A$646,MATCH(A34,'collectionMethodDistinct'!$A$2:$A$646,FALSE),1),"") -> Box corer
A35: Bulk Sample | B35: unknown | D35: =IFERROR(INDEX([1]SamplingMethod!$A$2:$C$160,MATCH(B35,[1]SamplingMethod!$C$2:$C$160,FALSE),1),"") -> 151 | E35: =IFERROR(INDEX([1]SamplingMethod!$A$2:$C$160,MATCH(B35,[1]SamplingMethod!$C$2:$C$160,FALSE),2),"") -> secm:unknown | F35: =IFERROR(INDEX('collectionMethodDistinct'!$A$2:$A$646,MATCH(A35,'collectionMethodDistinct'!$A$2:$A$646,FALSE),1),"") -> Bulk Sample
A36: CA-IDTIMS | B36: Other sampling procedure | D36: =IFERROR(INDEX([1]SamplingMethod!$A$2:$C$160,MATCH(B36,[1]SamplingMethod!$C$2:$C$160,FALSE),1),"") -> 142 | E36: =IFERROR(INDEX([1]SamplingMethod!$A$2:$C$160,MATCH(B36,[1]SamplingMethod!$C$2:$C$160,FALSE),2),"") -> secm:sm044 | F36: =IFERROR(INDEX('collectionMethodDistinct'!$A$2:$A$646,MATCH(A36,'collectionMethodDistinct'!$A$2:$A$646,FALSE),1),"") -> CA-IDTIMS
A37: Camera Grab | B37: Mechanical grab from surface | D37: =IFERROR(INDEX([1]SamplingMethod!$A$2:$C$160,MATCH(B37,[1]SamplingMethod!$C$2:$C$160,FALSE),1),"") -> 83 | E37: =IFERROR(INDEX([1]SamplingMethod!$A$2:$C$160,MATCH(B37,[1]SamplingMethod!$C$2:$C$160,FALSE),2),"") -> secm:ses222 | F37: =IFERROR(INDEX('collectionMethodDistinct'!$A$2:$A$646,MATCH(A37,'collectionMethodDistinct'!$A$2:$A$646,FALSE),1),"") -> Camera Grab
A38: Camera Grab/Blake Trawl | B38: Blake trawl | C38: Mechanical grab from surface | D38: =IFERROR(INDEX([1]SamplingMethod!$A$2:$C$160,MATCH(B38,[1]SamplingMethod!$C$2:$C$160,FALSE),1),"") -> 68 | E38: =IFERROR(INDEX([1]SamplingMethod!$A$2:$C$160,MATCH(B38,[1]SamplingMethod!$C$2:$C$160,FALSE),2),"") -> secm:ses204 | F38: =IFERROR(INDEX('collectionMethodDistinct'!$A$2:$A$646,MATCH(A38,'collectionMethodDistinct'!$A$2:$A$646,FALSE),1),"") -> Camera Grab/Blake Trawl
A39: Camera Sled | B39: Other sampling procedure | D39: =IFERROR(INDEX([1]SamplingMethod!$A$2:$C$160,MATCH(B39,[1]SamplingMethod!$C$2:$C$160,FALSE),1),"") -> 142 | E39: =IFERROR(INDEX([1]SamplingMethod!$A$2:$C$160,MATCH(B39,[1]SamplingMethod!$C$2:$C$160,FALSE),2),"") -> secm:sm044 | F39: =IFERROR(INDEX('collectionMethodDistinct'!$A$2:$A$646,MATCH(A39,'collectionMethodDistinct'!$A$2:$A$646,FALSE),1),"") -> Camera Sled
A40: Camera SledCamera tow | B40: Other sampling procedure | D40: =IFERROR(INDEX([1]SamplingMethod!$A$2:$C$160,MATCH(B40,[1]SamplingMethod!$C$2:$C$160,FALSE),1),"") -> 142 | E40: =IFERROR(INDEX([1]SamplingMethod!$A$2:$C$160,MATCH(B40,[1]SamplingMethod!$C$2:$C$160,FALSE),2),"") -> secm:sm044 | F40: =IFERROR(INDEX('collectionMethodDistinct'!$A$2:$A$646,MATCH(A40,'collectionMethodDistinct'!$A$2:$A$646,FALSE),1),"") -> Camera SledCamera tow
...

Sheet collectionMethodDistinct
A1: Column1 | B1: Column2
A2: method | B2: =IFERROR(INDEX(samplemethodlookup!$A$2:$D$648,MATCH(collectionMethodDistinct[[#This Row],[Column1]],samplemethodlookup!$A$2:$A$648,FALSE),1),"")
A3: Coring>JumboPistonCorer | B3: =IFERROR(INDEX(samplemethodlookup!$A$2:$D$648,MATCH(collectionMethodDistinct[[#This Row],[Column1]],samplemethodlookup!$A$2:$A$648,FALSE),1),"") -> Coring>JumboPistonCorer
A4: Shop bought - Northern Geological Supplies Ltd | B4: =IFERROR(INDEX(samplemethodlookup!$A$2:$D$648,MATCH(collectionMethodDistinct[[#This Row],[Column1]],samplemethodlookup!$A$2:$A$648,FALSE),1),"") -> Shop bought - Northern Geological Supplies Ltd
A5: Coring>HandHeldCorer | B5: =IFERROR(INDEX(samplemethodlookup!$A$2:$D$648,MATCH(collectionMethodDistinct[[#This Row],[Column1]],samplemethodlookup!$A$2:$A$648,FALSE),1),"") -> Coring>HandHeldCorer
A6: Cut from American Museum of Natural History Mineral Collection # 100242 | B6: =IFERROR(INDEX(samplemethodlookup!$A$2:$D$648,MATCH(collectionMethodDistinct[[#This Row],[Column1]],samplemethodlookup!$A$2:$A$648,FALSE),1),"") -> Cut from American Museum of Natural History Mineral Collection # 100242
A7: >2 mm size fraction | B7: =IFERROR(INDEX(samplemethodlookup!$A$2:$D$648,MATCH(collectionMethodDistinct[[#This Row],[Column1]],samplemethodlookup!$A$2:$A$648,FALSE),1),"") -> >2 mm size fraction
A8: >38 um size fraction | B8: =IFERROR(INDEX(samplemethodlookup!$A$2:$D$648,MATCH(collectionMethodDistinct[[#This Row],[Column1]],samplemethodlookup!$A$2:$A$648,FALSE),1),"") -> >38 um size fraction
A9: >63 um size fraction | B9: =IFERROR(INDEX(samplemethodlookup!$A$2:$D$648,MATCH(collectionMethodDistinct[[#This Row],[Column1]],samplemethodlookup!$A$2:$A$648,FALSE),1),"") -> >63 um size fraction
A10: 0.22 µm, PES | B10: =IFERROR(INDEX(samplemethodlookup!$A$2:$D$648,MATCH(collectionMethodDistinct[[#This Row],[Column1]],samplemethodlookup!$A$2:$A$648,FALSE),1),"") -> 0.22 µm, PES
A11: 0.22μm | B11: =IFERROR(INDEX(samplemethodlookup!$A$2:$D$648,MATCH(collectionMethodDistinct[[#This Row],[Column1]],samplemethodlookup!$A$2:$A$648,FALSE),1),"") -> 0.22μm
A12: 0.45 µm, PES | B12: =IFERROR(INDEX(samplemethodlookup!$A$2:$D$648,MATCH(collectionMethodDistinct[[#This Row],[Column1]],samplemethodlookup!$A$2:$A$648,FALSE),1),"") -> 0.45 µm, PES
A13: 0.45μm | B13: =IFERROR(INDEX(samplemethodlookup!$A$2:$D$648,MATCH(collectionMethodDistinct[[#This Row],[Column1]],samplemethodlookup!$A$2:$A$648,FALSE),1),"") -> 0.45μm
... A646: NULL | B646: =IFERROR(INDEX(samplemethodlookup!$A$2:$D$648,MATCH(collectionMethodDistinct[[#This Row],[Column1]],samplemethodlookup!$A$2:$A$648,FALSE),1),"") -> NULL

Sheet vocab
A1: redux | B1: ID | C1: parent term | D1: parentID | E1: source | F1: scope_note | G1: skos | H1: genus | I1: environment | J1: target material type | K1: type
A2: Composite water sample preserved with reagent | B2: sm001 | C2: Composite water sample | D2: sm010 | E2: e.g. see http://www.azdeq.gov/environ/water/assessment/download/sampling.pdf | F2: composite water sample preserved with reagent (e.g. nitric acid sulfuric acid) as part of sampling process | G2: {="secm:" & ID & " rdf:type skos:Concept ; skos:prefLabel """ & redux & """@en ; skos:inScheme secm:samplingmethods ; skos:definition """ & scope_note & """; skos:broader secm:" & parentID & " ; dcterms:source """ & source & """@en ; ."} -> secm:sm001 rdf:type skos:Concept ; skos:prefLabel "Composite water sample preserved with reagent"@en ; skos:inScheme secm:samplingmethods ; skos:definition "composite water sample preserved with reagent (e.g. nitric acid sulfuric acid) as part of sampling process"; skos:broader secm:sm010 ; dcterms:source "e.g. see http://www.azdeq.gov/environ/water/assessment/download/sampling.pdf"@en ; . | H2: sm100 | I2: sub aqueous | J2: water | K2: composite
A3: Composite water sample filtered | B3: sm002 | C3: Composite water sample | D3: sm010 | E3: e.g. see http://www.azdeq.gov/environ/water/assessment/download/sampling.pdf | F3: composite water sample filtered as part of the sampling process (in the field or within a very short time period after collection) | G3: secm:sm002 rdf:type skos:Concept ; skos:prefLabel "Composite water sample filtered"@en ; skos:inScheme secm:samplingmethods ; skos:definition "composite water sample filtered as part of the sampling process (in the field or within a very short time period after collection)"; skos:broader secm:sm010 ; dcterms:source "e.g. see http://www.azdeq.gov/environ/water/assessment/download/sampling.pdf"@en ; . | H3: sm100 | I3: sub aqueous | J3: water | K3: composite
A4: Composite water sample filtered preserved with reagent | B4: sm003 | C4: Composite water sample | D4: sm010 | E4: e.g. see http://www.azdeq.gov/environ/water/assessment/download/sampling.pdf | F4: composite filtered water sample preserved with reagent (e.g. nitric acid sulfuric acid) as part of sampling process | G4: secm:sm003 rdf:type skos:Concept ; skos:prefLabel "Composite water sample filtered preserved with reagent"@en ; skos:inScheme secm:samplingmethods ; skos:definition "composite filtered water sample preserved with reagent (e.g. nitric acid sulfuric acid) as part of sampling process"; skos:broader secm:sm010 ; dcterms:source "e.g. see http://www.azdeq.gov/environ/water/assessment/download/sampling.pdf"@en ; . | H4: sm100 | I4: sub aqueous | J4: water | K4: composite
A5: Drilled core | B5: sm004 | C5: Coring | D5: sm041 | E5: SESAR collection method | F5: core extracted from rock or sediment by a rotating hollow cylindrical bit | G5: secm:sm004 rdf:type skos:Concept ; skos:prefLabel "Drilled core"@en ; skos:inScheme secm:samplingmethods ; skos:definition "core extracted from rock or sediment by a rotating hollow cylindrical bit"; skos:broader secm:sm041 ; dcterms:source "SESAR collection method"@en ; . | H5: sm100 | I5: sub aqueous | J5: rock or sediment | K5: simple
A6: Soft sediment corer | B6: sm005 | C6: Coring | D6: sm041 | E6: SESAR collection method | F6: General category for methods to extract columnar samples perpendicular to the depositional surface from sediment that is poorly enough consolidated that it can be sampled without drilling. | G6: secm:sm005 rdf:type skos:Concept ; skos:prefLabel "Soft sediment corer"@en ; skos:inScheme secm:samplingmethods ; skos:definition "General category for methods to extract columnar samples perpendicular to the depositional surface from sediment that is poorly enough consolidated that it can be sampled without drilling."; skos:broader secm:sm041 ; dcterms:source "SESAR collection method"@en ; . | H6: sm100 | I6: shallow subsurface | J6: sediment | K6: simple
A7: Chain Bag Dredge | B7: sm006 | C7: Dredging | D7: sm033 | E7: SESAR collection method; http://www.deepreef.org/technology/79-rock-dredge.html | F7: A rock dredge is a large bag made of metal chain links attached to a simple heavy frame that keeps the bag expanded. The dredge is lowered off the back of a ship to the seafloor and dragged along to collect large pieces of rock. Because of the coarse chain links most of the finer material is washed out of the bag leaving behind the larger rock and gravel pieces within the chain bag. The dredge is then winched up to the surface and any samples are dumped onto the deck of the ship to be sorted and preserved. | G7: secm:sm006 rdf:type skos:Concept ; skos:prefLabel "Chain Bag Dredge"@en ; skos:inScheme secm:samplingmethods ; skos:definition "A rock dredge is a large bag made of metal chain links attached to a simple heavy frame that keeps the bag expanded. The dredge is lowered off the back of a ship to the seafloor and dragged along to collect large pieces of rock. Because of the coarse chain links most of the finer material is washed out of the bag leaving behind the larger rock and gravel pieces within the chain bag. The dredge is then winched up to the surface and any samples are dumped onto the deck of the ship to be sorted and preserved."; skos:broader secm:sm033 ; dcterms:source "SESAR collection method; http://www.deepreef.org/technology/79-rock-dredge.html"@en ; . | H7: sm100 | I7: sub aqueous | J7: rock or sediment | K7: composite
A8: Hand auger coring | B8: sm007 | C8: Drilled core | D8: sm004 | E8: this vocabulary; http://www.oakenviro.com/pdfs/Dutch%20Auger%20equipment%20options%20-%20Eijkelkamp.pdf | F8: core extracted from sediment or soil by a hand rotated tool with a special bit that extracts short segments of cored sediment; many variations in design. | G8: secm:sm007 rdf:type skos:Concept ; skos:prefLabel "Hand auger coring"@en ; skos:inScheme secm:samplingmethods ; skos:definition "core extracted from sediment or soil by a hand rotated tool with a special bit that extracts short segments of cored sediment; many variations in design. "; skos:broader secm:sm004 ; dcterms:source "this vocabulary; http://www.oakenviro.com/pdfs/Dutch%20Auger%20equipment%20options%20-%20Eijkelkamp.pdf"@en ; . | H8: sm100 | I8: shallow subsurface | J8: sediment/soil | K8: simple
A9: Inverted funnel to evacuated bottle gas collection | B9: sm008 | C9: Evacuated bottle gas sampling | D9: sm011 | F9: Gas is collected from a bubbling subaqueous gas source by inverting a suitable size and composition funnel over the gas source connected by a tube to a evacuated bottle gas collector. | G9: secm:sm008 rdf:type skos:Concept ; skos:prefLabel "Inverted funnel to evacuated bottle gas collection"@en ; skos:inScheme secm:samplingmethods ; skos:definition "Gas is collected from a bubbling subaqueous gas source by inverting a suitable size and composition funnel over the gas source connected by a tube to a evacuated bottle gas collector."; skos:broader secm:sm011 ; dcterms:source ""@en ; . | H9: sm100 | I9: sub aqueous | J9: gas | K9: simple
A10: Inverted funnel to flow through bottle gas collection | B10: sm009 | C10: Flow through bottle gas sampling | D10: sm012 | F10: Gas is collected from a bubbling subaqueous gas source by inverting a suitable size and composition funnel over the gas source connected by a tube to a flow through bottle gas collector. | G10: secm:sm009 rdf:type skos:Concept ; skos:prefLabel "Inverted funnel to flow through bottle gas collection"@en ; skos:inScheme secm:samplingmethods ; skos:definition "Gas is collected from a bubbling subaqueous gas source by inverting a suitable size and composition funnel over the gas source connected by a tube to a flow through bottle gas collector."; skos:broader secm:sm012 ; dcterms:source ""@en ; . | H10: sm100 | I10: sub aqueous | J10: gas | K10: simple
A11: Composite water sample | B11: sm010 | C11: Fluid collected into container | D11: sm043 | E11: e.g. see http://www.azdeq.gov/environ/water/assessment/download/sampling.pdf | F11: water sample collected through some documented process over an extended water volume meant to characterize that volume e.g. a profile in a lake a stream cross section or some volume in the ocean. Many different processes may be used to collect subsamples and aggregate them into a representative single sample. | G11: secm:sm010 rdf:type skos:Concept ; skos:prefLabel "Composite water sample"@en ; skos:inScheme secm:samplingmethods ; skos:definition "water sample collected through some documented process over an extended water volume meant to characterize that volume e.g. a profile in a lake a stream cross section or some volume in the ocean. Many different processes may be used to collect subsamples and aggregate them into a representative single sample."; skos:broader secm:sm043 ; dcterms:source "e.g. see http://www.azdeq.gov/environ/water/assessment/download/sampling.pdf"@en ; . | H11: sm100 | I11: sub aqueous | J11: water | K11: composite
A12: Evacuated bottle gas sampling | B12: sm011 | C12: Fluid collected into container | D12: sm043 | E12: http://volcanoes.usgs.gov/activity/methods/gas/sample.php | F12: Insert a suitable chemically inert and durable tube (e.g. titanium quartz alumina or mullite) into gas source. After allowing the tube to heat until condensation in the tube has reached equilibrium with the escaping gases usually about 5 minutes a specially-designed bottle with a high-vacuum stopcock and sample port is attached to the collection tube. Before arriving at the sampling site the bottle is partially filled with concentrated aqueous sodium hydroxide carefully weighed and evacuated with a vacuum pump. As gases bubble through the alkaline solution acid gases such as CO2 H2S SO2 HCl and HF dissolve into the liquid. The remaining gases such as N2 O2 H2 CO and He collect in the headspace of the bottle. For gas is composed mostly of water and condensable acid gases many liters of gas can be collected in a single bottle. This method concentrates gases in the solution and headspace and thereby promotes better analytical precision. Typically used for hot (volcanic geothermal) gas collection. | G12: secm:sm011 rdf:type skos:Concept ; skos:prefLabel "Evacuated bottle gas sampling"@en ; skos:inScheme secm:samplingmethods ; skos:definition "Insert a suitable chemically inert and durable tube (e.g. titanium quartz alumina or mullite) into gas source. After allowing the tube to heat until condensation in the tube has reached equilibrium with the escaping gases usually about 5 minutes a specially-designed bottle with a high-vacuum stopcock and sample port is attached to the collection tube. Before arriving at the sampling site the bottle is partially filled with concentrated aqueous sodium hydroxide carefully weighed and evacuated with a vacuum pump. As gases bubble through the alkaline solution acid gases such as CO2 H2S SO2 HCl and HF dissolve into the liquid. The remaining gases such as N2 O2 H2 CO and He collect in the headspace of the bottle. For gas is composed mostly of water and condensable acid gases many liters of gas can be collected in a single bottle. This method concentrates gases in the solution and headspace and thereby promotes better analytical precision. Typically used for hot (volcanic geothermal) gas collection."; skos:broader secm:sm043 ; dcterms:source "http://volcanoes.usgs.gov/activity/methods/gas/sample.php"@en ; . | H12: sm100 | I12: anyEnvironment | J12: gas | K12: simple
A13: Flow through bottle gas sampling | B13: sm012 | C13: Fluid collected into container | D13: sm043 | E13: http://volcanoes.usgs.gov/activity/methods/gas/sample.php | F13: Insert a suitable chemically inert and durable tube (e.g. titanium quartz alumina or mullite) into gas source. After allowing the tube to heat until condensation in the tube has reached equilibrium with the escaping gases usually about 5 minutes a specially-designed flow-through sample bottle with a stopcock at each end and a hand-operated pump is attached to the collection tubing. The hand pump flushes out air and draws the gas into the bottle. This collection method is faster that the evacuated bottle method. It is used when a complete gas analysis is not necessary or where field conditions are too hazardous to safely make an evacuated-bottle collection. Sulfur gases are stable for only a short time so this type of sample must be analyzed within a few hours of collection. | G13: secm:sm012 rdf:type skos:Concept ; skos:prefLabel "Flow through bottle gas sampling"@en ; skos:inScheme secm:samplingmethods ; skos:definition "Insert a suitable chemically inert and durable tube (e.g. titanium quartz alumina or mullite) into gas source. After allowing the tube to heat until condensation in the tube has reached equilibrium with the escaping gases usually about 5 minutes a specially-designed flow-through sample bottle with a stopcock at each end and a hand-operated pump is attached to the collection tubing. The hand pump flushes out air and draws the gas into the bottle. This collection method is faster that the evacuated bottle method. It is used when a complete gas analysis is not necessary or where field conditions are too hazardous to safely make an evacuated-bottle collection. Sulfur gases are stable for only a short time so this type of sample must be analyzed within a few hours of collection."; skos:broader secm:sm043 ; dcterms:source "http://volcanoes.usgs.gov/activity/methods/gas/sample.php"@en ; . | H13: sm100 | I13: anyEnvironment | J13: gas | K13: simple
A14: Other gas sampling apparatus | B14: sm013 | C14: Fluid collected into container | D14: sm043 | E14: this vocabulary | F14: general class for gas sampling methods | G14: secm:sm013 rdf:type skos:Concept ; skos:prefLabel "Other gas sampling apparatus"@en ; skos:inScheme secm:samplingmethods ; skos:definition "general class for gas sampling methods"; skos:broader secm:sm043 ; dcterms:source "this vocabulary"@en ; . | H14: sm100 | I14: surface | J14: gas | K14: any
A15: Simple water sample | B15: sm014 | C15: Fluid collected into container | D15: sm043 | E15: e.g. see http://www.azdeq.gov/environ/water/assessment/download/sampling.pdf | F15: water collected into a suitable container from a single sampling point. Includes grab sample from stream samples collected by machines that open and close sampling bottles as the device is lowered through water column. e.g. Van Dorn bottles Kemmerer Water Sampler | G15: secm:sm014 rdf:type skos:Concept ; skos:prefLabel "Simple water sample"@en ; skos:inScheme secm:samplingmethods ; skos:definition "water collected into a suitable container from a single sampling point. Includes grab sample from stream samples collected by machines that open and close sampling bottles as the device is lowered through water column. e.g. Van Dorn bottles Kemmerer Water Sampler"; skos:broader secm:sm043 ; dcterms:source "e.g. see http://www.azdeq.gov/environ/water/assessment/download/sampling.pdf"@en ; . | H15: sm100 | I15: sub aqueous | J15: water | K15: simple
A16: Channel sample | B16: sm015 | C16: Manual grab | D16: sm035 | E16: USGS Circular; Vernon E. Swanson and Claude Huffman Jr. 1976 GUIDELINES FOR SAMPLE COLLECTING AND ANALYTICAL METHODS USED IN THE U.S. GEOLOGICAL SURVEY FOR DETERMINING CHEMICAL COMPOSITION OF COAL: U. S. Geological Survey CIRCULAR 735. accessed at http://energy.er.usgs.gov/products/databases/CoalQual/Docs/c735.pdf | F16: chip an approximately 3-inch by 3-inch (7.5 cm by 7.5 cm) channel accross the sampled feature (e.g. a coal bed) with a chisel or pick-point hammer producing fragments 2 inches (5 cm) or less across. Positioning a horizontal plastic sheet below the level of channel cutting is sometimes helpful. May also be applied to sampling at regular intervals along a channel or trench cut across a surface. | G16: secm:sm015 rdf:type skos:Concept ; skos:prefLabel "Channel sample"@en ; skos:inScheme secm:samplingmethods ; skos:definition "chip an approximately 3-inch by 3-inch (7.5 cm by 7.5 cm) channel accross the sampled feature (e.g. a coal bed) with a chisel or pick-point hammer producing fragments 2 inches (5 cm) or less across. Positioning a horizontal plastic sheet below the level of channel cutting is sometimes helpful. May also be applied to sampling at regular intervals along a channel or trench cut across a surface."; skos:broader secm:sm035 ; dcterms:source "USGS Circular; Vernon E. Swanson and Claude Huffman Jr. 1976 GUIDELINES FOR SAMPLE COLLECTING AND ANALYTICAL METHODS USED IN THE U.S. GEOLOGICAL SURVEY FOR DETERMINING CHEMICAL COMPOSITION OF COAL: U. S. Geological Survey CIRCULAR 735. accessed at http://energy.er.usgs.gov/products/databases/CoalQual/Docs/c735.pdf"@en ; . | H16: sm100 | I16: surface | J16: any | K16: composite
A17: Collected from outcrop | B17: sm016 | C17: Manual grab | D17: sm035 | E17: this vocabulary | F17: specimen obtained by breaking piece(s) of rock from rock outcrop on surface or in a subsurface tunnel | G17: secm:sm016 rdf:type skos:Concept ; skos:prefLabel "Collected from outcrop"@en ; skos:inScheme secm:samplingmethods ; skos:definition "specimen obtained by breaking piece(s) of rock from rock outcrop on surface or in a subsurface tunnel"; skos:broader secm:sm035 ; dcterms:source "this vocabulary"@en ; . | H17: sm100 | I17: surface | J17: rock | K17: simple
A18: Manual surface grab | B18: sm017 | C18: Manual grab | D18: sm035 | E18: this vocabulary | F18: specimen obtained from loose material on surface e.g. from talus colluvium mine heap. | G18: secm:sm017 rdf:type skos:Concept ; skos:prefLabel "Manual surface grab"@en ; skos:inScheme secm:samplingmethods ; skos:definition "specimen obtained from loose material on surface e.g. from talus colluvium mine heap."; skos:broader secm:sm035 ; dcterms:source "this vocabulary"@en ; . | H18: sm100 | I18: surface | J18: rock | K18: any
A19: Sediment trap | B19: sm018 | C19: Other sampling appartus | D19: sm044 | E19: SESAR collection method; http://www.whoi.edu/instruments/viewInstrument.do?id=10286 | F19: Sediment traps are containers that scientists place in the water to collect particles falling toward the sea floor. The basic sediment trap consists of a broad funnel with a collecting jar at the bottom. The funnel opening covers a standard area (such as 0.25 square meter [2.7 square feet]) and has baffles at the top to keep out very large objects that might clog the funnel. | G19: secm:sm018 rdf:type skos:Concept ; skos:prefLabel "Sediment trap"@en ; skos:inScheme secm:samplingmethods ; skos:definition "Sediment traps are containers that scientists place in the water to collect particles falling toward the sea floor. The basic sediment trap consists of a broad funnel with a collecting jar at the bottom. The funnel opening covers a standard area (such as 0.25 square meter [2.7 square feet]) and has baffles at the top to keep out very large objects that might clog the funnel. "; skos:broader secm:sm044 ; dcterms:source "SESAR collection method; http://www.whoi.edu/instruments/viewInstrument.do?id=10286"@en ; . | H19: sm100 | I19: sub aqueous | J19: sediment | K19: simple
A20: Panned concentrate | B20: sm019 | C20: Processed separation | D20: sm045 | E20: this vocabulary | F20: use of a gold-miners pan to concentrate heavy minerals from a loose sediment (typcially stream sediment) sample | G20: secm:sm019 rdf:type skos:Concept ; skos:prefLabel "Panned concentrate"@en ; skos:inScheme secm:samplingmethods ; skos:definition "use of a gold-miners pan to concentrate heavy minerals from a loose sediment (typcially stream sediment) sample"; skos:broader secm:sm045 ; dcterms:source "this vocabulary"@en ; . | H20: sm100 | I20: continental | J20: sediment | K20: simple
A21: Split processed sample | B21: sm020 | C21: Processed separation | D21: sm045 | E21: this vocabulary | F21: mechanical separation of part a processed sample; e.g. taking grains from a mineral separate splitting a powdered sample splitting a crushed sample | G21: secm:sm020 rdf:type skos:Concept ; skos:prefLabel "Split processed sample"@en ; skos:inScheme secm:samplingmethods ; skos:definition "mechanical separation of part a processed sample; e.g. taking grains from a mineral separate splitting a powdered sample splitting a crushed sample"; skos:broader secm:sm045 ; dcterms:source "this vocabulary"@en ; . | H21: sm100 | J21: any | K21: derived
A22: Suspended sediment separate | B22: sm021 | C22: Processed separation | D22: sm045 | E22: SESAR collection method; this vocabulary | F22: suspended sediment separated from containing water by filtration or centrifuge. | G22: secm:sm021 rdf:type skos:Concept ; skos:prefLabel "Suspended sediment separate"@en ; skos:inScheme secm:samplingmethods ; skos:definition "suspended sediment separated from containing water by filtration or centrifuge."; skos:broader secm:sm045 ; dcterms:source "SESAR collection method; this vocabulary"@en ; . | H22: sm100 | I22: sub aqueous | J22: sediment | K22: simple
A23: Simple water sample preserved with reagent | B23: sm022 | C23: Simple water sample | D23: sm014 | E23: e.g. see http://www.azdeq.gov/environ/water/assessment/download/sampling.pdf | F23: simple water sample preserved with reagent (e.g. nitric acid sulfuric acid) as part of sampling process | G23: secm:sm022 rdf:type skos:Concept ; skos:prefLabel "Simple water sample preserved with reagent"@en ; skos:inScheme secm:samplingmethods ; skos:definition "simple water sample preserved with reagent (e.g. nitric acid sulfuric acid) as part of sampling process"; skos:broader secm:sm014 ; dcterms:source "e.g. see http://www.azdeq.gov/environ/water/assessment/download/sampling.pdf"@en ; . | H23: sm100 | I23: sub aqueous | J23: water | K23: simple
A24: Simple water sample filtered | B24: sm023 | C24: Simple water sample | D24: sm014 | E24: e.g. see http://www.azdeq.gov/environ/water/assessment/download/sampling.pdf | F24: simple water sample filtered as part of the sampling process (in the field or within a very short time period after collection) | G24: secm:sm023 rdf:type skos:Concept ; skos:prefLabel "Simple water sample filtered"@en ; skos:inScheme secm:samplingmethods ; skos:definition "simple water sample filtered as part of the sampling process (in the field or within a very short time period after collection)"; skos:broader secm:sm014 ; dcterms:source "e.g. see http://www.azdeq.gov/environ/water/assessment/download/sampling.pdf"@en ; . | H24: sm100 | I24: sub aqueous | J24: water | K24: simple
A25: Simple water sample filtered preserved with reagent | B25: sm024 | C25: Simple water sample | D25: sm014 | E25: e.g. see http://www.azdeq.gov/environ/water/assessment/download/sampling.pdf | F25: simple filtered water sample preserved with reagent (e.g. nitric acid sulfuric acid) as part of sampling process | G25: secm:sm024 rdf:type skos:Concept ; skos:prefLabel "Simple water sample filtered preserved with reagent"@en ; skos:inScheme secm:samplingmethods ; skos:definition "simple filtered water sample preserved with reagent (e.g. nitric acid sulfuric acid) as part of sampling process"; skos:broader secm:sm014 ; dcterms:source "e.g. see http://www.azdeq.gov/environ/water/assessment/download/sampling.pdf"@en ; . | H25: sm100 | I25: sub aqueous | J25: water | K25: simple
A26: Box Corer | B26: sm025 | C26: Soft sediment corer | D26: sm005 | E26: SESAR collection method; http://www.deepreef.org/technology/9-grab.html; http://www.eu-hermione.net/box-core; http://www.azdeq.gov/environ/water/assessment/download/sampling.pdf (Eckman dredge) | F26: A box core uses trigger plates that contact the seafloor to close the top and bottom of a metal box plunged into the seabed. This device neatly extracts a plug of sediment that is mostly undisturbed and allows scientists to examine the layers of sediment carefully and any marine life found within. Use this category for Eckman Dredge samples as well | G26: secm:sm025 rdf:type skos:Concept ; skos:prefLabel "Box Corer"@en ; skos:inScheme secm:samplingmethods ; skos:definition " A box core uses trigger plates that contact the seafloor to close the top and bottom of a metal box plunged into the seabed. This device neatly extracts a plug of sediment that is mostly undisturbed and allows scientists to examine the layers of sediment carefully and any marine life found within. Use this category for Eckman Dredge samples as well"; skos:broader secm:sm005 ; dcterms:source "SESAR collection method; http://www.deepreef.org/technology/9-grab.html; http://www.eu-hermione.net/box-core; http://www.azdeq.gov/environ/water/assessment/download/sampling.pdf (Eckman dredge)"@en ; . | H26: sm100 | I26: shallow subsurface | J26: sediment | K26: simple
A27: Gravity Corer | B27: sm026 | C27: Soft sediment corer | D27: sm005 | E27: SESAR collection method; http://www.whoi.edu/instruments/viewInstrument.do?id=8087 http://www.whoi.edu/instruments/viewInstrument.do?id=1079 | F27: A gravity corer is just a weighted pipe that is allowed to free fall into the water. | G27: secm:sm026 rdf:type skos:Concept ; skos:prefLabel "Gravity Corer"@en ; skos:inScheme secm:samplingmethods ; skos:definition "A gravity corer is just a weighted pipe that is allowed to free fall into the water."; skos:broader secm:sm005 ; dcterms:source "SESAR collection method; http://www.whoi.edu/instruments/viewInstrument.do?id=8087 http://www.whoi.edu/instruments/viewInstrument.do?id=1079"@en ; . | H27: sm100 | I27: shallow subsurface | J27: sediment | K27: simple
A28: Hand Held Corer | B28: sm027 | C28: Soft sediment corer | D28: sm005 | E28: SESAR collection method | F28: collects core by operator pushing the core tube into the sediment to be sampled; may be assisted by vibration induced in the core tube | G28: secm:sm027 rdf:type skos:Concept ; skos:prefLabel "Hand Held Corer"@en ; skos:inScheme secm:samplingmethods ; skos:definition "collects core by operator pushing the core tube into the sediment to be sampled; may be assisted by vibration induced in the core tube"; skos:broader secm:sm005 ; dcterms:source "SESAR collection method"@en ; . | H28: sm100 | I28: shallow subsurface | J28: sediment | K28: simple
A29: MultiCorer | B29: sm028 | C29: Soft sediment corer | D29: sm005 | E29: SESAR collection method; http://polardiscovery.whoi.edu/expedition5/tools_multicore.html | F29: sampling by pushing a device into seafloor sediments that extracts many tubular samples of sediment at once. The multicore has a cone-shaped aluminum frame. In the middle are eight plastic tubes. When the frame settles on the floor the center of the multicore slowly and evenly pushes the tubes into the sediment. The tubes are capped at the top and bottom and the multicore comes back to the surface with eight samples of sediment. | G29: secm:sm028 rdf:type skos:Concept ; skos:prefLabel "MultiCorer"@en ; skos:inScheme secm:samplingmethods ; skos:definition "sampling by pushing a device into seafloor sediments that extracts many tubular samples of sediment at once. The multicore has a cone-shaped aluminum frame. In the middle are eight plastic tubes. When the frame settles on the floor the center of the multicore slowly and evenly pushes the tubes into the sediment. The tubes are capped at the top and bottom and the multicore comes back to the surface with eight samples of sediment."; skos:broader secm:sm005 ; dcterms:source "SESAR collection method; http://polardiscovery.whoi.edu/expedition5/tools_multicore.html"@en ; . | H29: sm100 | I29: shallow subsurface | J29: sediment | K29: either
A30: Piston Corer | B30: sm029 | C30: Soft sediment corer | D30: sm005 | E30: SESAR collection method; http://www.whoi.edu/instruments/gallery.do?mainid=17288&iid=8087; http://www.tdi-bi.com/field_services/sge_info/piston_coring.htm | F30: Piston corers have a piston mechanism that is triggered when the corer hits the bottom. The piston helps to avoid disturbing the sediment. As the piston corer penetrates the seafloor the piston inside stops at the sediment surface. The action of the piston creates a pressure differential at the top of the sediment column. This allows the soft material to enter the core liner without disruption. A piston corer uses a _free fall_ of the coring rig to achieve a greater initial force on impact than gravity coring and a sliding piston inside the core barrel to reduce inside wall friction with the sediment and to assist in the evacuation of displaced water from the top of the corer. The piston-coring rig is comprised of a trigger assembly the coring weight assembly core barrels tip assembly and piston. | G30: secm:sm029 rdf:type skos:Concept ; skos:prefLabel "Piston Corer"@en ; skos:inScheme secm:samplingmethods ; skos:definition "Piston corers have a piston mechanism that is triggered when the corer hits the bottom. The piston helps to avoid disturbing the sediment. As the piston corer penetrates the seafloor the piston inside stops at the sediment surface. The action of the piston creates a pressure differential at the top of the sediment column. This allows the soft material to enter the core liner without disruption. A piston corer uses a _free fall_ of the coring rig to achieve a greater initial force on impact than gravity coring and a sliding piston inside the core barrel to reduce inside wall friction with the sediment and to assist in the evacuation of displaced water from the top of the corer. The piston-coring rig is comprised of a trigger assembly the coring weight assembly core barrels tip assembly and piston."; skos:broader secm:sm005 ; dcterms:source "SESAR collection method; http://www.whoi.edu/instruments/gallery.do?mainid=17288&iid=8087; http://www.tdi-bi.com/field_services/sge_info/piston_coring.htm"@en ; . | H30: sm100 | I30: shallow subsurface | J30: sediment | K30: simple
A31: Probe core | B31: sm030 | C31: Soft sediment corer | D31: sm005 | E31: SESAR collection method; http://www.fandm.edu/earth-and-environment/sediment-sampling-methods | F31: Soil or sediment collected by pneumatically pushing or pounding a sleeve through soft sediments via a rig mounted on the back of a pick-up truck or on an ATV. Note: Sediment in cores commonly is compressed to 30-50% of the in situ volume. Wildco corer. | G31: secm:sm030 rdf:type skos:Concept ; skos:prefLabel "Probe core"@en ; skos:inScheme secm:samplingmethods ; skos:definition "Soil or sediment collected by pneumatically pushing or pounding a sleeve through soft sediments via a rig mounted on the back of a pick-up truck or on an ATV. Note: Sediment in cores commonly is compressed to 30-50% of the in situ volume. Wildco corer."; skos:broader secm:sm005 ; dcterms:source "SESAR collection method; http://www.fandm.edu/earth-and-environment/sediment-sampling-methods"@en ; . | H31: sm100 | I31: shallow subsurface | J31: sediment | K31: simple
A32: Vibrating Corer | B32: sm031 | C32: Soft sediment corer | D32: sm005 | E32: SESAR collection method; http://www.vibracoring.com/vcconcepts.html | F32: Vibracoring (or vibrocoring) is a technology and a technique for collecting core samples of underwater sediments and wetland soils. The vibrating mechanism of a vibracorer sometimes called the _vibrahead_ operates on hydraulic pneumatic mechanical or electrical power from an external source. The attached core tube is driven into sediment by the force of gravity enhanced by vibration energy. When the insertion is completed the vibracorer is turned off and the tube is withdrawn with the aid of hoist equipment. | G32: secm:sm031 rdf:type skos:Concept ; skos:prefLabel "Vibrating Corer"@en ; skos:inScheme secm:samplingmethods ; skos:definition "Vibracoring (or vibrocoring) is a technology and a technique for collecting core samples of underwater sediments and wetland soils. The vibrating mechanism of a vibracorer sometimes called the _vibrahead_ operates on hydraulic pneumatic mechanical or electrical power from an external source. The attached core tube is driven into sediment by the force of gravity enhanced by vibration energy. When the insertion is completed the vibracorer is turned off and the tube is withdrawn with the aid of hoist equipment. "; skos:broader secm:sm005 ; dcterms:source "SESAR collection method; http://www.vibracoring.com/vcconcepts.html"@en ; . | H32: sm100 | I32: shallow subsurface | J32: sediment | K32: simple
A33: Blasting | B33: sm032 | C33: Surface grab | D33: sm047 | E33: SESAR collection method | F33: sample collected from rock material freed from outcrop by explosives; similar to surface grab in that precise location of specimen in the rock body is not precisely known | G33: secm:sm032 rdf:type skos:Concept ; skos:prefLabel "Blasting"@en ; skos:inScheme secm:samplingmethods ; skos:definition "sample collected from rock material freed from outcrop by explosives; similar to surface grab in that precise location of specimen in the rock body is not precisely known"; skos:broader secm:sm047 ; dcterms:source "SESAR collection method"@en ; . | H33: sm100 | I33: surface | J33: rock | K33: NA
... A45: Other sampling appartus | B45: sm044 | C45: Top | D45: sm100 | E45: this vocabulary | F45: Specimen obtained using some mechnical process not identified in this vocabulary | G45: secm:sm044 rdf:type skos:Concept ; skos:prefLabel "Other sampling appartus"@en ; skos:inScheme secm:samplingmethods ; skos:definition "Specimen obtained using some mechnical process not identified in this vocabulary"; skos:broader secm:sm100 ; dcterms:source "this vocabulary"@en ; . | H45: sm100 | I45: anyEnvironment | J45: any | K45: any
A46: Processed separation | B46: sm045 | C46: Top | D46: sm100 | E46: this vocabulary | F46: separation of part of a sample by some lab technique; have to look at processing method for details. E.g. density separation magnetic separation insoluble residue hand picking. Too many possibilities to categorize each subsampling method. | G46: secm:sm045 rdf:type skos:Concept ; skos:prefLabel "Processed separation"@en ; skos:inScheme secm:samplingmethods ; skos:definition "separation of part of a sample by some lab technique; have to look at processing method for details. E.g. density separation magnetic separation insoluble residue hand picking. Too many possibilities to categorize each subsampling method."; skos:broader secm:sm100 ; dcterms:source "this vocabulary"@en ; . | H46: sm100 | J46: any | K46: derived
A47: Split bulk sample | B47: sm046 | C47: Top | D47: sm100 | E47: this vocabulary | F47: mechanical separation of part of a bulk sample. E.g. breaking a hand sample up with a hammer and taking pieces splitting material in a bagged sample | G47: secm:sm046 rdf:type skos:Concept ; skos:prefLabel "Split bulk sample"@en ; skos:inScheme secm:samplingmethods ; skos:definition "mechanical separation of part of a bulk sample. E.g. breaking a hand sample up with a hammer and taking pieces splitting material in a bagged sample"; skos:broader secm:sm100 ; dcterms:source "this vocabulary"@en ; . | H47: sm100 | J47: any | K47: derived
A48: Surface grab | B48: sm047 | C48: Top | D48: sm100 | E48: this vocabulary | F48: Specimen obtained by picking up material from a surface; may involve breaking material away from outcrop or picking up loose material on surface | G48: secm:sm047 rdf:type skos:Concept ; skos:prefLabel "Surface grab "@en ; skos:inScheme secm:samplingmethods ; skos:definition "Specimen obtained by picking up material from a surface; may involve breaking material away from outcrop or picking up loose material on surface"; skos:broader secm:sm100 ; dcterms:source "this vocabulary"@en ; . | H48: sm100 | I48: anyEnvironment | J48: rock or sediment | K48: any
A49: Top | B49: sm100 | C49: Top | D49: sm100 | F49: top concept | G49: secm:sm100 rdf:type skos:Concept ; skos:prefLabel "Top"@en ; skos:inScheme secm:samplingmethods ; skos:definition "top concept"; skos:broader secm:sm100 ; dcterms:source ""@en ; . | H49: sm100
A50: Agassiz trawl | B50: ses200 | C50: Top | D50: sm100 | G50: secm:ses200 rdf:type skos:Concept ; skos:prefLabel "Agassiz trawl"@en ; skos:inScheme secm:samplingmethods ; skos:definition ""; skos:broader secm:sm100 ; dcterms:source ""@en ; .
A51: ALVIN grab | B51: ses201 | C51: Surface grab | D51: sm047 | G51: secm:ses201 rdf:type skos:Concept ; skos:prefLabel "ALVIN grab"@en ; skos:inScheme secm:samplingmethods ; skos:definition ""; skos:broader secm:sm047 ; dcterms:source ""@en ; .
...
