Workbook

Sheet initiativeVocab
A1: initiative_id | B1: label | C1: count | D1: platform_name_verbatim | E1: platform_name_label | F1: start | G1: end | H1: notes | I1: uri | J1: initiative_type
A2: -9999 | B2: check
A3: 2 | B3: 01/01/04n/r | C3: =COUNTIF($B$3:$B$4219,B3) -> 1 | F3: 37986.708 | G3: 37986.708 | H3: 3 samples, small craft, lake and terrestrial
A4: 3 | B4: 1000 Soils Pilot | C4: =COUNTIF($B$3:$B$4219,B4) -> 1 | E4: Unknown | F4: 44458.875 | G4: 44595.917 | J4: Soil Sampling
A5: 4 | B5: 17ARC | C5: =COUNTIF($B$3:$B$4219,B5) -> 1 | F5: 42586.875 | G5: 42961.875
A6: 5 | B6: 1880-05-12 | C6: =COUNTIF($B$3:$B$4219,B6) -> 1 | F6: NULL | G6: NULL
A7: 6 | B7: 1979 Field Work | C7: =COUNTIF($B$3:$B$4219,B7) -> 1 | E7: N.A. | F7: 29036.875 | G7: 29036.875 | J7: Field campaign
A8: 7 | B8: 1986 SEA CLIFF dive program (Escanaba Trough) | C8: =COUNTIF($B$3:$B$4219,B8) -> 1 | F8: NULL | G8: NULL
A9: 8 | B9: 1994 NOAA cruise | C9: =COUNTIF($B$3:$B$4219,B9) -> 1 | F9: NULL | G9: NULL
A10: 9 | B10: 19OCS | C10: =COUNTIF($B$3:$B$4219,B10) -> 1 | D10: R/V APALACHEE | E10: R/V APALACHEE | F10: 43741.875 | G10: 43741.875
A11: 10 | B11: 2004 MARGINS | C11: =COUNTIF($B$3:$B$4219,B11) -> 1 | F11: 38091.875 | G11: 38099.875
A12: 11 | B12: 2005 MARGINS | C12: =COUNTIF($B$3:$B$4219,B12) -> 1 | F12: 38095.875 | G12: 38095.875
A13: 12 | B13: 2006 MARGINS | C13: =COUNTIF($B$3:$B$4219,B13) -> 1 | F13: 38095.875 | G13: 38095.875
A14: 13 | B14: 2007 MARGINS | C14: =COUNTIF($B$3:$B$4219,B14) -> 1 | F14: 38095.875 | G14: 38095.875
A15: 14 | B15: 2008 MARGINS | C15: =COUNTIF($B$3:$B$4219,B15) -> 1 | F15: 38095.875 | G15: 38095.875
A16: 15 | B16: 2009 MARGINS | C16: =COUNTIF($B$3:$B$4219,B16) -> 1 | F16: 38095.875 | G16: 38095.875
A17: 16 | B17: 2009 Northern Expedition | C17: =COUNTIF($B$3:$B$4219,B17) -> 1 | D17: R/V Western Flyer | E17: R/V Western Flyer | F17: 40044.558 | G17: 40056.881
A18: 17 | B18: 2012 Field Campaign | C18: =COUNTIF($B$3:$B$4219,B18) -> 1 | E18: N.A. | F18: 40768.708 | G18: 40768.708 | J18: Field campaign
A19: 18 | B19: 2013 Himalaya Fieldwork | C19: =COUNTIF($B$3:$B$4219,B19) -> 1 | E19: N.A. | F19: 41281.917 | G19: 41281.917 | J19: Field campaign
A20: 19 | B20: 2013 summer field season | C20: =COUNTIF($B$3:$B$4219,B20) -> 1 | E20: N.A. | F20: 41455.875 | G20: 41455.875 | J20: Field campaign
A21: 20 | B21: 2013, 2014 summer field campaign | C21: =COUNTIF($B$3:$B$4219,B21) -> 1 | E21: N.A. | F21: 41274.917 | G21: 41274.917 | J21: Field campaign
A22: 21 | B22: 2014 Field Season | C22: =COUNTIF($B$3:$B$4219,B22) -> 1 | E22: N.A. | F22: 41723.875 | G22: 41723.875 | J22: Field campaign
A23: 22 | B23: 2015 Himalaya Fieldwork | C23: =COUNTIF($B$3:$B$4219,B23) -> 1 | E23: N.A. | F23: 42316.917 | G23: 42318.917 | J23: Field campaign
A24: 23 | B24: 2018 Arbuckle Mountains Fieldwork | C24: =COUNTIF($B$3:$B$4219,B24) -> 1 | E24: N.A. | F24: 43244.875 | G24: 43254.875 | J24: Field campaign
A25: 24 | B25: 2018 Himalaya Fieldwork | C25: =COUNTIF($B$3:$B$4219,B25) -> 1 | E25: N.A. | F25: 43110.917 | G25: 43110.917 | J25: Field campaign
A26: 25 | B26: 2019 STATEMAP | C26: =COUNTIF($B$3:$B$4219,B26) -> 1 | E26: N.A. | F26: NULL | G26: NULL | J26: Field campaign
A27: 26 | B27: 2020 Himalaya Fieldwork | C27: =COUNTIF($B$3:$B$4219,B27) -> 1 | E27: N.A. | F27: 43843.917 | G27: 43844.917 | J27: Field campaign
A28: 27 | B28: 2023 Aboveground Productivity Net Primary Production | C28: =COUNTIF($B$3:$B$4219,B28) -> 1 | D28: 4 | E28: platform 04 | F28: 45138.875 | G28: 45138.875 | H28: platforms 04 to 21
A29: 28 | B29: 2023 Grenville orogen | C29: =COUNTIF($B$3:$B$4219,B29) -> 1 | E29: Unknown | F29: 45134.875 | G29: 45143.875
A30: 29 | B30: 2024 JULY ALPI ORIENTALI | C30: =COUNTIF($B$3:$B$4219,B30) -> 1 | F30: 45479.342 | G30: 45480.301
A31: 30 | B31: 20XRZC | C31: =COUNTIF($B$3:$B$4219,B31) -> 1 | F31: NULL | G31: NULL
A32: 31 | B32: 21WL | C32: =COUNTIF($B$3:$B$4219,B32) -> 1 | F32: NULL | G32: NULL
A33: 32 | B33: 2PI | C33: =COUNTIF($B$3:$B$4219,B33) -> 1 | D33: R/V Akademik Boris Petrov | E33: R/V Akademik Boris Petrov | F33: 31047.917 | G33: 31047.917
A34: 33 | B34: 3RPD | C34: =COUNTIF($B$3:$B$4219,B34) -> 1 | F34: 42743.917 | G34: 42743.917
A35: 34 | B35: 40th Parallel Survey | C35: =COUNTIF($B$3:$B$4219,B35) -> 1 | F35: NULL | G35: NULL
A36: 35 | B36: 7TOW04WT | C36: =COUNTIF($B$3:$B$4219,B36) -> 1 | D36: T. Washington | E36: R/V Thomas Washington | F36: NULL | G36: NULL
A37: 36 | B37: 7TOW05WT | C37: =COUNTIF($B$3:$B$4219,B37) -> 1 | D37: T. Washington | E37: R/V Thomas Washington | F37: NULL | G37: NULL
A38: 37 | B38: 7TOW06WT | C38: =COUNTIF($B$3:$B$4219,B38) -> 1 | D38: T. Washington | E38: R/V Thomas Washington | F38: NULL | G38: NULL
A39: 38 | B39: 91-AV-19/2 | C39: =COUNTIF($B$3:$B$4219,B39) -> 1 | D39: Aleksandr Vinogradov | E39: Akademik Aleksandr Vinogradov | F39: NULL | G39: NULL
A40: 39 | B40: A150 | C40: =COUNTIF($B$3:$B$4219,B40) -> 1 | D40: Atlantis | E40: Atlantis? | F40: NULL | G40: NULL | H40: can't tell what this is supposd to be
...

Sheet initiativeLookup
A1: cruise_field_prgrm_verbatim | B1: label | C1: initiative_id | D1: platform_name_verbatim | E1: platform_name_label | F1: start | G1: end | H1: notes | I1: uri | J1: initiative_type
A2: 1 | B2: ="cruise or field program " & TEXT(A2,"00") -> cruise or field program 01 | C2: 912 | F2: 33602.917 | G2: 33602.917
A3: 2 | B3: ="cruise or field program " & TEXT(A3,"00") -> cruise or field program 02 | C3: 913 | F3: 34817.875 | G3: 36159.917
A4: 3 | B4: ="cruise or field program " & TEXT(A4,"00") -> cruise or field program 03 | C4: 914 | F4: 37089.875 | G4: 37090.875
A5: 4 | B5: ="cruise or field program " & TEXT(A5,"00") -> cruise or field program 04 | C5: 915 | F5: 37255.917 | G5: 37255.917
A6: 5 | B6: ="cruise or field program " & TEXT(A6,"00") -> cruise or field program 05 | C6: 916 | F6: 34726.917 | G6: 34727.917
A7: 7 | B7: ="cruise or field program " & TEXT(A7,"00") -> cruise or field program 07 | C7: 917 | F7: 31776.917 | G7: 31776.917
A8: 8 | B8: ="cruise or field program " & TEXT(A8,"00") -> cruise or field program 08 | C8: 918 | F8: NULL | G8: NULL
A9: 9 | B9: ="cruise or field program " & TEXT(A9,"00") -> cruise or field program 09 | C9: 919 | F9: 29585.917 | G9: 33602.917
A10: 10 | B10: ="cruise or field program " & TEXT(A10,"00") -> cruise or field program 10 | C10: 920 | F10: 35854.917 | G10: 35854.917
A11: 12 | B11: ="cruise or field program " & TEXT(A11,"00") -> cruise or field program 12 | C11: 922 | F11: 37620.917 | G11: 37620.917
A12: 13 | B12: ="cruise or field program " & TEXT(A12,"00") -> cruise or field program 13 | C12: 923 | F12: 34698.917 | G12: 34698.917
A13: 14 | B13: ="cruise or field program " & TEXT(A13,"00") -> cruise or field program 14 | C13: 924 | F13: 38887.875 | G13: 38887.875
A14: 15 | B14: ="cruise or field program " & TEXT(A14,"00") -> cruise or field program 15 | C14: 925 | F14: 31411.917 | G14: 31411.917
A15: 16 | B15: ="cruise or field program " & TEXT(A15,"00") -> cruise or field program 16 | C15: 926 | F15: 36524.917 | G15: 37255.917
A16: 17 | B16: ="cruise or field program " & TEXT(A16,"00") -> cruise or field program 17 | C16: 927 | F16: 31776.917 | G16: 31776.917
A17: 18 | B17: ="cruise or field program " & TEXT(A17,"00") -> cruise or field program 18 | C17: 928 | F17: 36524.917 | G17: 36524.917
A18: 19 | B18: ="cruise or field program " & TEXT(A18,"00") -> cruise or field program 19 | C18: 930 | F18: 34030.917 | G18: 36261.875
A19: 20 | B19: ="cruise or field program " & TEXT(A19,"00") -> cruise or field program 20 | C19: 931 | F19: 31717.917 | G19: 31717.917
A20: 21 | B20: ="cruise or field program " & TEXT(A20,"00") -> cruise or field program 21 | C20: 933 | F20: 34195.875 | G20: 34195.875
... A23: 24 | B23: ="cruise or field program " & TEXT(A23,"00") -> cruise or field program 24 | C23: 937 | F23: 32872.917 | G23: 36890.917
A24: 25 | B24: ="cruise or field program " & TEXT(A24,"00") -> cruise or field program 25 | C24: 938 | F24: NULL | G24: NULL
A25: 26 | B25: ="cruise or field program " & TEXT(A25,"00") -> cruise or field program 26 | C25: 939 | F25: NULL | G25: NULL
A26: 27 | B26: ="cruise or field program " & TEXT(A26,"00") -> cruise or field program 27 | C26: 940 | F26: 32010.875 | G26: 35429.917
A27: 28 | B27: ="cruise or field program " & TEXT(A27,"00") -> cruise or field program 28 | C27: 941 | F27: 37255.917 | G27: 37255.917
A28: 29 | B28: ="cruise or field program " & TEXT(A28,"00") -> cruise or field program 29 | C28: 942 | F28: 35794.917 | G28: 36159.917
A29: 30 | B29: ="cruise or field program " & TEXT(A29,"00") -> cruise or field program 30 | C29: 943 | F29: 31820.917 | G29: 31820.917
A30: 31 | B30: ="cruise or field program " & TEXT(A30,"00") -> cruise or field program 31 | C30: 944 | F30: 35794.917 | G30: 35794.917
A31: 32 | B31: ="cruise or field program " & TEXT(A31,"00") -> cruise or field program 32 | C31: 945 | F31: 33603.917 | G31: 33603.917
A32: 33 | B32: ="cruise or field program " & TEXT(A32,"00") -> cruise or field program 33 | C32: 946 | F32: 35794.917 | G32: 35794.917
A33: 34 | B33: ="cruise or field program " & TEXT(A33,"00") -> cruise or field program 34 | C33: 947 | F33: NULL | G33: NULL
A34: 35 | B34: ="cruise or field program " & TEXT(A34,"00") -> cruise or field program 35 | C34: 948 | F34: 37255.917 | G34: 37255.917
A35: 36 | B35: ="cruise or field program " & TEXT(A35,"00") -> cruise or field program 36 | C35: 949 | F35: 29219.917 | G35: 35429.917
A36: 37 | B36: ="cruise or field program " & TEXT(A36,"00") -> cruise or field program 37 | C36: 950 | F36: NULL | G36: NULL
A37: 38 | B37: ="cruise or field program " & TEXT(A37,"00") -> cruise or field program 38 | C37: 951 | F37: 29950.917 | G37: 29950.917
A38: 39 | B38: ="cruise or field program " & TEXT(A38,"00") -> cruise or field program 39 | C38: 952 | F38: 37620.917 | G38: 37620.917
A39: 40 | B39: ="cruise or field program " & TEXT(A39,"00") -> cruise or field program 40 | C39: 953 | F39: 34967.875 | G39: 34974.875
A40: 42 | B40: ="cruise or field program " & TEXT(A40,"00") -> cruise or field program 42 | C40: 954 | F40: 36159.917 | G40: 36159.917
A41: 43 | B41: ="cruise or field program " & TEXT(A41,"00") -> cruise or field program 43 | C41: 955 | F41: 24012.875 | G41: 37737.875
A42: 44 | B42: ="cruise or field program " & TEXT(A42,"00") -> cruise or field program 44 | C42: 956 | F42: 35429.917 | G42: 35429.917
...

Sheet PlatformLookup
A1: platform_name_verbatim | B1: platform_name_label | C1: platform_id
A2: 4 | B2: platform 04 | C2: =IFERROR(INDEX([1]PlatformVocabulary!$A$2:$B$320,MATCH(B2,[1]PlatformVocabulary!$B$2:$B$320,FALSE),1),"") -> 133
A3: 5 | B3: platform 05 | C3: =IFERROR(INDEX([1]PlatformVocabulary!$A$2:$B$320,MATCH(B3,[1]PlatformVocabulary!$B$2:$B$320,FALSE),1),"") -> 134
A4: 6 | B4: platform 06 | C4: =IFERROR(INDEX([1]PlatformVocabulary!$A$2:$B$320,MATCH(B4,[1]PlatformVocabulary!$B$2:$B$320,FALSE),1),"") -> 135
A5: 7 | B5: platform 07 | C5: =IFERROR(INDEX([1]PlatformVocabulary!$A$2:$B$320,MATCH(B5,[1]PlatformVocabulary!$B$2:$B$320,FALSE),1),"") -> 136
A6: 8 | B6: platform 08 | C6: =IFERROR(INDEX([1]PlatformVocabulary!$A$2:$B$320,MATCH(B6,[1]PlatformVocabulary!$B$2:$B$320,FALSE),1),"") -> 137
A7: 9 | B7: platform 09 | C7: =IFERROR(INDEX([1]PlatformVocabulary!$A$2:$B$320,MATCH(B7,[1]PlatformVocabulary!$B$2:$B$320,FALSE),1),"") -> 138
A8: 10 | B8: platform 10 | C8: =IFERROR(INDEX([1]PlatformVocabulary!$A$2:$B$320,MATCH(B8,[1]PlatformVocabulary!$B$2:$B$320,FALSE),1),"") -> 139
A9: 11 | B9: platform 11 | C9: =IFERROR(INDEX([1]PlatformVocabulary!$A$2:$B$320,MATCH(B9,[1]PlatformVocabulary!$B$2:$B$320,FALSE),1),"") -> 140
A10: 13 | B10: platform 13 | C10: =IFERROR(INDEX([1]PlatformVocabulary!$A$2:$B$320,MATCH(B10,[1]PlatformVocabulary!$B$2:$B$320,FALSE),1),"") -> 141
A11: 14 | B11: platform 14 | C11: =IFERROR(INDEX([1]PlatformVocabulary!$A$2:$B$320,MATCH(B11,[1]PlatformVocabulary!$B$2:$B$320,FALSE),1),"") -> 142
A12: 15 | B12: platform 15 | C12: =IFERROR(INDEX([1]PlatformVocabulary!$A$2:$B$320,MATCH(B12,[1]PlatformVocabulary!$B$2:$B$320,FALSE),1),"") -> 143
A13: 16 | B13: platform 16 | C13: =IFERROR(INDEX([1]PlatformVocabulary!$A$2:$B$320,MATCH(B13,[1]PlatformVocabulary!$B$2:$B$320,FALSE),1),"") -> 144
... A18: 510 | B18: platform 510 | C18: =IFERROR(INDEX([1]PlatformVocabulary!$A$2:$B$320,MATCH(B18,[1]PlatformVocabulary!$B$2:$B$320,FALSE),1),"") -> 149
A19: -- | B19: Missing | C19: =IFERROR(INDEX([1]PlatformVocabulary!$A$2:$B$320,MATCH(B19,[1]PlatformVocabulary!$B$2:$B$320,FALSE),1),"") -> -9999
A20: R/V JOIDES Resolution | B20: D/V JOIDES Resolution | C20: =IFERROR(INDEX([1]PlatformVocabulary!$A$2:$B$320,MATCH(B20,[1]PlatformVocabulary!$B$2:$B$320,FALSE),1),"") -> 48
A21: RV Maman Benita | B21: R/V Maman Benita | C21: =IFERROR(INDEX([1]PlatformVocabulary!$A$2:$B$320,MATCH(B21,[1]PlatformVocabulary!$B$2:$B$320,FALSE),1),"") -> 187
A22: RV Minnow | B22: R/V Minnow | C22: =IFERROR(INDEX([1]PlatformVocabulary!$A$2:$B$320,MATCH(B22,[1]PlatformVocabulary!$B$2:$B$320,FALSE),1),"") -> 194
A23: Adriatico | B23: Adriatico | C23: =IFERROR(INDEX([1]PlatformVocabulary!$A$2:$B$320,MATCH(B23,[1]PlatformVocabulary!$B$2:$B$320,FALSE),1),"") -> 1
A24: Agulhas | B24: Agulhas | C24: =IFERROR(INDEX([1]PlatformVocabulary!$A$2:$B$320,MATCH(B24,[1]PlatformVocabulary!$B$2:$B$320,FALSE),1),"") -> 2
A25: Akademik B. Petrov | B25: R/V Akademik Boris Petrov | C25: =IFERROR(INDEX([1]PlatformVocabulary!$A$2:$B$320,MATCH(B25,[1]PlatformVocabulary!$B$2:$B$320,FALSE),1),"") -> 158
A26: Akademik Boris Petrov | B26: R/V Akademik Boris Petrov | C26: =IFERROR(INDEX([1]PlatformVocabulary!$A$2:$B$320,MATCH(B26,[1]PlatformVocabulary!$B$2:$B$320,FALSE),1),"") -> 158
A27: Akademik Kurchatov | B27: R/V Akademik Kurchatov | C27: =IFERROR(INDEX([1]PlatformVocabulary!$A$2:$B$320,MATCH(B27,[1]PlatformVocabulary!$B$2:$B$320,FALSE),1),"") -> 159
A28: Akademik M.A. Lavrentyev | B28: Akademik M.A. Lavrentyev | C28: =IFERROR(INDEX([1]PlatformVocabulary!$A$2:$B$320,MATCH(B28,[1]PlatformVocabulary!$B$2:$B$320,FALSE),1),"") -> 4
A29: Alaminos | B29: Alaminos | C29: =IFERROR(INDEX([1]PlatformVocabulary!$A$2:$B$320,MATCH(B29,[1]PlatformVocabulary!$B$2:$B$320,FALSE),1),"") -> 5
A30: Albatross | B30: Albatross | C30: =IFERROR(INDEX([1]PlatformVocabulary!$A$2:$B$320,MATCH(B30,[1]PlatformVocabulary!$B$2:$B$320,FALSE),1),"") -> 6
... A392: Thalassa | B392: Thalassa | C392: =IFERROR(INDEX([1]PlatformVocabulary!$A$2:$B$320,MATCH(B392,[1]PlatformVocabulary!$B$2:$B$320,FALSE),1),"") -> 288
B393: N.A. | C393: =IFERROR(INDEX([1]PlatformVocabulary!$A$2:$B$320,MATCH(B393,[1]PlatformVocabulary!$B$2:$B$320,FALSE),1),"") -> 110
A394: Theta | B394: Theta | C394: =IFERROR(INDEX([1]PlatformVocabulary!$A$2:$B$320,MATCH(B394,[1]PlatformVocabulary!$B$2:$B$320,FALSE),1),"") -> 289
A395: Thomas G Thompson | B395: R/V Thomas G. Thompson | C395: =IFERROR(INDEX([1]PlatformVocabulary!$A$2:$B$320,MATCH(B395,[1]PlatformVocabulary!$B$2:$B$320,FALSE),1),"") -> 221
A396: Thomas G. Thompson | B396: R/V Thomas G. Thompson | C396: =IFERROR(INDEX([1]PlatformVocabulary!$A$2:$B$320,MATCH(B396,[1]PlatformVocabulary!$B$2:$B$320,FALSE),1),"") -> 221
A397: THOMAS THOMPSON | B397: R/V Thomas G. Thompson | C397: =IFERROR(INDEX([1]PlatformVocabulary!$A$2:$B$320,MATCH(B397,[1]PlatformVocabulary!$B$2:$B$320,FALSE),1),"") -> 221
A398: Thomas Washington | B398: R/V Thomas Washington | C398: =IFERROR(INDEX([1]PlatformVocabulary!$A$2:$B$320,MATCH(B398,[1]PlatformVocabulary!$B$2:$B$320,FALSE),1),"") -> 222
A399: Thompson | B399: R/V Thomas G. Thompson | C399: =IFERROR(INDEX([1]PlatformVocabulary!$A$2:$B$320,MATCH(B399,[1]PlatformVocabulary!$B$2:$B$320,FALSE),1),"") -> 221
A400: TN154 | B400: TN154 | C400: =IFERROR(INDEX([1]PlatformVocabulary!$A$2:$B$320,MATCH(B400,[1]PlatformVocabulary!$B$2:$B$320,FALSE),1),"") -> 290
A401: Touchwood, 38 degrees South | B401: Touchwood, 38 degrees South | C401: =IFERROR(INDEX([1]PlatformVocabulary!$A$2:$B$320,MATCH(B401,[1]PlatformVocabulary!$B$2:$B$320,FALSE),1),"") -> 291
A402: TowCam | B402: TowCam | C402: =IFERROR(INDEX([1]PlatformVocabulary!$A$2:$B$320,MATCH(B402,[1]PlatformVocabulary!$B$2:$B$320,FALSE),1),"") -> 292
A403: Trident | B403: R/V Trident | C403: =IFERROR(INDEX([1]PlatformVocabulary!$A$2:$B$320,MATCH(B403,[1]PlatformVocabulary!$B$2:$B$320,FALSE),1),"") -> 223
A404: Trieste | B404: Trieste | C404: =IFERROR(INDEX([1]PlatformVocabulary!$A$2:$B$320,MATCH(B404,[1]PlatformVocabulary!$B$2:$B$320,FALSE),1),"") -> 293
A405: U.S.S. Nero | B405: U.S.S. Nero | C405: =IFERROR(INDEX([1]PlatformVocabulary!$A$2:$B$320,MATCH(B405,[1]PlatformVocabulary!$B$2:$B$320,FALSE),1),"") -> 294
...
